Workbook

Sheet Assumptions
A1: 150-Key Luxury Resort – Pro Forma Assumptions
A3: Operating Drivers | B3: Jan | C3: Feb | D3: Mar | E3: Apr | F3: May | G3: Jun | H3: Jul | I3: Aug | J3: Sep | K3: Oct | L3: Nov | M3: Dec | N3: YTD / Annual
A4: Total Keys | B4: 150 | C4: 150 | D4: 150 | E4: 150 | F4: 150 | G4: 150 | H4: 150 | I4: 150 | J4: 150 | K4: 150 | L4: 150 | M4: 150 | N4: =B4 -> 150
A5: Days per Month | B5: 30 | C5: 30 | D5: 30 | E5: 30 | F5: 30 | G5: 30 | H5: 30 | I5: 30 | J5: 30 | K5: 30 | L5: 30 | M5: 30 | N5: =SUM(B5:M5) -> 360
A6: Occupancy | B6: 0.75 | C6: 0.72 | D6: 0.66 | E6: 0.64 | F6: 0.52 | G6: 0.62 | H6: 0.75 | I6: 0.73 | J6: 0.52 | K6: 0.55 | L6: 0.68 | M6: 0.66 | N6: =AVERAGE(B6:M6) -> 0.65
A7: ADR ($) | B7: 269.05 | C7: 264.16 | D7: 244.59 | E7: 239.7 | F7: 220.13 | G7: 239.7 | H7: 269.05 | I7: 264.16 | J7: 220.13 | K7: 225.03 | L7: 249.49 | M7: 269.05 | N7: =SUMPRODUCT(B6:M6,B7:M7)/SUM(B6:M6) -> 249.99824
A9: Baseline P&L Assumptions
A10: Assumption | B10: Baseline | C10: Formula / Meaning | D10: Source / Note
A11: F&B Revenue / Rooms Revenue | B11: 0.4 | C11: F&B Revenue = Rooms Revenue × % | D11: User-provided prompt
A12: Spa/Other Revenue / Rooms Revenue | B12: 0.1 | C12: Other Operated Dept Revenue = Rooms Revenue × % | D12: User-provided prompt
A13: Rooms Payroll & Related / Rooms Rev | B13: 0.14 | C13: Rooms Payroll = Rooms Revenue × % | D13: Model baseline within requested 75%–78% Rooms profit margin
A14: Distribution Commissions / Rooms Rev | B14: 0.03 | C14: Distribution Commissions = Rooms Revenue × effective commission rate | D14: Illustrative blended distribution commission cost; OTA and brand marketing expenditure is modeled separately under S&M.
A15: Rooms Other OpEx / Rooms Rev | B15: 0.06 | C15: Rooms Other OpEx = Rooms Revenue × % | D15: Model baseline
A16: F&B COGS / F&B Rev | B16: 0.3 | C16: F&B COGS = F&B Revenue × % | D16: User requested approx. 30%
A17: F&B Payroll & Related / F&B Rev | B17: 0.35 | C17: F&B Payroll = F&B Revenue × % | D17: User requested approx. 35%
A18: F&B Other OpEx / F&B Rev | B18: 0.125 | C18: F&B Other OpEx = F&B Revenue × % | D18: Sets F&B departmental profit margin to 22.5%
A19: Spa/Other Payroll / Other Rev | B19: 0.4 | C19: Spa/Other Payroll = Other Revenue × % | D19: Model baseline
A20: Spa/Other Other OpEx / Other Rev | B20: 0.225 | C20: Spa/Other Other OpEx = Other Revenue × % | D20: Sets Other Dept profit margin to 37.5%
A21: A&G / Total Operating Revenue | B21: 0.09 | C21: A&G = Total Operating Revenue × % | D21: Within requested 8%–10%
A22: IT&S / Total Operating Revenue | B22: 0.015 | C22: IT&S = Total Operating Revenue × % | D22: Added for USALI 11 completeness; HFTP lists IT&S as an undistributed department
... A28: FF&E Reserve / Total Revenue | B28: 0.04 | C28: FF&E Reserve = Total Operating Revenue × % | D28: User-provided prompt

Sheet Pro Forma P&L
A1: 150-Key Luxury Resort – 12-Month Pro Forma P&L (USD)
A3: Line Item | B3: Jan | C3: Feb | D3: Mar | E3: Apr | F3: May | G3: Jun | H3: Jul | I3: Aug | J3: Sep | K3: Oct | L3: Nov | M3: Dec | N3: YTD / Annual
A4: Available Rooms | B4: =Assumptions!B$4*Assumptions!B$5 -> 4500 | C4: =Assumptions!C$4*Assumptions!C$5 -> 4500 | D4: =Assumptions!D$4*Assumptions!D$5 -> 4500 | E4: =Assumptions!E$4*Assumptions!E$5 -> 4500 | F4: =Assumptions!F$4*Assumptions!F$5 -> 4500 | G4: =Assumptions!G$4*Assumptions!G$5 -> 4500 | H4: =Assumptions!H$4*Assumptions!H$5 -> 4500 | I4: =Assumptions!I$4*Assumptions!I$5 -> 4500 | ... M4: =Assumptions!M$4*Assumptions!M$5 -> 4500 | N4: =SUM(B4:M4) -> 54000
A5: Occupancy | B5: =Assumptions!B$6 -> 0.75 | C5: =Assumptions!C$6 -> 0.72 | D5: =Assumptions!D$6 -> 0.66 | E5: =Assumptions!E$6 -> 0.64 | F5: =Assumptions!F$6 -> 0.52 | G5: =Assumptions!G$6 -> 0.62 | H5: =Assumptions!H$6 -> 0.75 | I5: =Assumptions!I$6 -> 0.73 | ... M5: =Assumptions!M$6 -> 0.66 | N5: =N6/N4 -> 0.65
A6: Rooms Sold | B6: =B4*B5 -> 3375 | C6: =C4*C5 -> 3240 | D6: =D4*D5 -> 2970 | E6: =E4*E5 -> 2880 | F6: =F4*F5 -> 2340 | G6: =G4*G5 -> 2790 | H6: =H4*H5 -> 3375 | I6: =I4*I5 -> 3285 | ... M6: =M4*M5 -> 2970 | N6: =SUM(B6:M6) -> 35100
A7: ADR | B7: =Assumptions!B$7 -> 269.05 | C7: =Assumptions!C$7 -> 264.16 | D7: =Assumptions!D$7 -> 244.59 | E7: =Assumptions!E$7 -> 239.7 | F7: =Assumptions!F$7 -> 220.13 | G7: =Assumptions!G$7 -> 239.7 | H7: =Assumptions!H$7 -> 269.05 | I7: =Assumptions!I$7 -> 264.16 | ... M7: =Assumptions!M$7 -> 269.05 | N7: =N10/N6 -> 249.99824
A9: OPERATING REVENUE
A10: Rooms Revenue | B10: =B6*B7 -> 908043.75 | C10: =C6*C7 -> 855878.4 | D10: =D6*D7 -> 726432.3 | E10: =E6*E7 -> 690336 | F10: =F6*F7 -> 515104.2 | G10: =G6*G7 -> 668763 | H10: =H6*H7 -> 908043.75 | I10: =I6*I7 -> 867765.6 | ... M10: =M6*M7 -> 799078.5 | N10: =SUM(B10:M10) -> 8774938.4
A11: Food & Beverage Revenue | B11: =B10*Assumptions!$B$11 -> 363217.5 | C11: =C10*Assumptions!$B$11 -> 342351.36 | D11: =D10*Assumptions!$B$11 -> 290572.92 | E11: =E10*Assumptions!$B$11 -> 276134.4 | F11: =F10*Assumptions!$B$11 -> 206041.68 | G11: =G10*Assumptions!$B$11 -> 267505.2 | H11: =H10*Assumptions!$B$11 -> 363217.5 | I11: =I10*Assumptions!$B$11 -> 347106.24 | ... M11: =M10*Assumptions!$B$11 -> 319631.4 | N11: =SUM(B11:M11) -> 3509975.3
A12: Other Operated Departments Revenue – Spa/Minor | B12: =B10*Assumptions!$B$12 -> 90804.375 | C12: =C10*Assumptions!$B$12 -> 85587.84 | D12: =D10*Assumptions!$B$12 -> 72643.23 | E12: =E10*Assumptions!$B$12 -> 69033.6 | F12: =F10*Assumptions!$B$12 -> 51510.42 | G12: =G10*Assumptions!$B$12 -> 66876.3 | H12: =H10*Assumptions!$B$12 -> 90804.375 | I12: =I10*Assumptions!$B$12 -> 86776.56 | ... M12: =M10*Assumptions!$B$12 -> 79907.85 | N12: =SUM(B12:M12) -> 877493.84
A13: Miscellaneous Income | B13: 0 | C13: 0 | D13: 0 | E13: 0 | F13: 0 | G13: 0 | H13: 0 | I13: 0 | J13: 0 | K13: 0 | L13: 0 | M13: 0 | N13: =SUM(B13:M13) -> 0
A14: Total Operating Revenue | B14: =SUM(B10:B13) -> 1362065.6 | C14: =SUM(C10:C13) -> 1283817.6 | D14: =SUM(D10:D13) -> 1089648.5 | E14: =SUM(E10:E13) -> 1035504 | F14: =SUM(F10:F13) -> 772656.3 | G14: =SUM(G10:G13) -> 1003144.5 | H14: =SUM(H10:H13) -> 1362065.6 | I14: =SUM(I10:I13) -> 1301648.4 | ... M14: =SUM(M10:M13) -> 1198617.8 | N14: =SUM(B14:M14) -> 13162408
A16: ROOMS DEPARTMENT
A17: Payroll & Related | B17: =B10*Assumptions!$B$13 -> 127126.13 | C17: =C10*Assumptions!$B$13 -> 119822.98 | D17: =D10*Assumptions!$B$13 -> 101700.52 | E17: =E10*Assumptions!$B$13 -> 96647.04 | F17: =F10*Assumptions!$B$13 -> 72114.588 | G17: =G10*Assumptions!$B$13 -> 93626.82 | H17: =H10*Assumptions!$B$13 -> 127126.13 | I17: =I10*Assumptions!$B$13 -> 121487.18 | ... M17: =M10*Assumptions!$B$13 -> 111870.99 | N17: =SUM(B17:M17) -> 1228491.4
A18: Rooms Distribution Commissions | B18: =B10*Assumptions!$B$14 -> 27241.312 | C18: =C10*Assumptions!$B$14 -> 25676.352 | D18: =D10*Assumptions!$B$14 -> 21792.969 | E18: =E10*Assumptions!$B$14 -> 20710.08 | F18: =F10*Assumptions!$B$14 -> 15453.126 | G18: =G10*Assumptions!$B$14 -> 20062.89 | H18: =H10*Assumptions!$B$14 -> 27241.312 | I18: =I10*Assumptions!$B$14 -> 26032.968 | ... M18: =M10*Assumptions!$B$14 -> 23972.355 | N18: =SUM(B18:M18) -> 263248.15
A19: Other Operating Expenses | B19: =B10*Assumptions!$B$15 -> 54482.625 | C19: =C10*Assumptions!$B$15 -> 51352.704 | D19: =D10*Assumptions!$B$15 -> 43585.938 | E19: =E10*Assumptions!$B$15 -> 41420.16 | F19: =F10*Assumptions!$B$15 -> 30906.252 | G19: =G10*Assumptions!$B$15 -> 40125.78 | H19: =H10*Assumptions!$B$15 -> 54482.625 | I19: =I10*Assumptions!$B$15 -> 52065.936 | ... M19: =M10*Assumptions!$B$15 -> 47944.71 | N19: =SUM(B19:M19) -> 526496.3
A20: Total Rooms Department Expenses | B20: =SUM(B17:B19) -> 208850.06 | C20: =SUM(C17:C19) -> 196852.03 | D20: =SUM(D17:D19) -> 167079.43 | E20: =SUM(E17:E19) -> 158777.28 | F20: =SUM(F17:F19) -> 118473.97 | G20: =SUM(G17:G19) -> 153815.49 | H20: =SUM(H17:H19) -> 208850.06 | I20: =SUM(I17:I19) -> 199586.09 | ... M20: =SUM(M17:M19) -> 183788.05 | N20: =SUM(B20:M20) -> 2018235.8
A21: Rooms Department Profit | B21: =B10-B20 -> 699193.69 | C21: =C10-C20 -> 659026.37 | D21: =D10-D20 -> 559352.87 | E21: =E10-E20 -> 531558.72 | F21: =F10-F20 -> 396630.23 | G21: =G10-G20 -> 514947.51 | H21: =H10-H20 -> 699193.69 | I21: =I10-I20 -> 668179.51 | ... M21: =M10-M20 -> 615290.45 | N21: =SUM(B21:M21) -> 6756702.5
A22: Rooms Department Profit Margin | B22: =B21/B10 -> 0.77 | C22: =C21/C10 -> 0.77 | D22: =D21/D10 -> 0.77 | E22: =E21/E10 -> 0.77 | F22: =F21/F10 -> 0.77 | G22: =G21/G10 -> 0.77 | H22: =H21/H10 -> 0.77 | I22: =I21/I10 -> 0.77 | ... N22: =N21/N10 -> 0.77
A24: FOOD & BEVERAGE DEPARTMENT
A25: Cost of Goods Sold | B25: =B11*Assumptions!$B$16 -> 108965.25 | C25: =C11*Assumptions!$B$16 -> 102705.41 | D25: =D11*Assumptions!$B$16 -> 87171.876 | E25: =E11*Assumptions!$B$16 -> 82840.32 | F25: =F11*Assumptions!$B$16 -> 61812.504 | G25: =G11*Assumptions!$B$16 -> 80251.56 | H25: =H11*Assumptions!$B$16 -> 108965.25 | I25: =I11*Assumptions!$B$16 -> 104131.87 | ... M25: =M11*Assumptions!$B$16 -> 95889.42 | N25: =SUM(B25:M25) -> 1052992.6
A26: Payroll & Related | B26: =B11*Assumptions!$B$17 -> 127126.12 | C26: =C11*Assumptions!$B$17 -> 119822.98 | D26: =D11*Assumptions!$B$17 -> 101700.52 | E26: =E11*Assumptions!$B$17 -> 96647.04 | F26: =F11*Assumptions!$B$17 -> 72114.588 | G26: =G11*Assumptions!$B$17 -> 93626.82 | H26: =H11*Assumptions!$B$17 -> 127126.12 | I26: =I11*Assumptions!$B$17 -> 121487.18 | ... M26: =M11*Assumptions!$B$17 -> 111870.99 | N26: =SUM(B26:M26) -> 1228491.4
A27: Other Operating Expenses | B27: =B11*Assumptions!$B$18 -> 45402.188 | C27: =C11*Assumptions!$B$18 -> 42793.92 | D27: =D11*Assumptions!$B$18 -> 36321.615 | E27: =E11*Assumptions!$B$18 -> 34516.8 | F27: =F11*Assumptions!$B$18 -> 25755.21 | G27: =G11*Assumptions!$B$18 -> 33438.15 | H27: =H11*Assumptions!$B$18 -> 45402.188 | I27: =I11*Assumptions!$B$18 -> 43388.28 | ... M27: =M11*Assumptions!$B$18 -> 39953.925 | N27: =SUM(B27:M27) -> 438746.92
A28: Total F&B Department Expenses | B28: =SUM(B25:B27) -> 281493.56 | C28: =SUM(C25:C27) -> 265322.3 | D28: =SUM(D25:D27) -> 225194.01 | E28: =SUM(E25:E27) -> 214004.16 | F28: =SUM(F25:F27) -> 159682.3 | G28: =SUM(G25:G27) -> 207316.53 | H28: =SUM(H25:H27) -> 281493.56 | I28: =SUM(I25:I27) -> 269007.34 | ... M28: =SUM(M25:M27) -> 247714.34 | N28: =SUM(B28:M28) -> 2720230.9
A29: F&B Department Profit | B29: =B11-B28 -> 81723.938 | C29: =C11-C28 -> 77029.056 | D29: =D11-D28 -> 65378.907 | E29: =E11-E28 -> 62130.24 | F29: =F11-F28 -> 46359.378 | G29: =G11-G28 -> 60188.67 | H29: =H11-H28 -> 81723.938 | I29: =I11-I28 -> 78098.904 | ... M29: =M11-M28 -> 71917.065 | N29: =SUM(B29:M29) -> 789744.45
A30: F&B Department Profit Margin | B30: =B29/B11 -> 0.225 | C30: =C29/C11 -> 0.225 | D30: =D29/D11 -> 0.225 | E30: =E29/E11 -> 0.225 | F30: =F29/F11 -> 0.225 | G30: =G29/G11 -> 0.225 | H30: =H29/H11 -> 0.225 | I30: =I29/I11 -> 0.225 | ... N30: =N29/N11 -> 0.225
A32: OTHER OPERATED DEPARTMENTS – SPA/MINOR
A33: Payroll & Related | B33: =B12*Assumptions!$B$19 -> 36321.75 | C33: =C12*Assumptions!$B$19 -> 34235.136 | D33: =D12*Assumptions!$B$19 -> 29057.292 | E33: =E12*Assumptions!$B$19 -> 27613.44 | F33: =F12*Assumptions!$B$19 -> 20604.168 | G33: =G12*Assumptions!$B$19 -> 26750.52 | H33: =H12*Assumptions!$B$19 -> 36321.75 | I33: =I12*Assumptions!$B$19 -> 34710.624 | ... M33: =M12*Assumptions!$B$19 -> 31963.14 | N33: =SUM(B33:M33) -> 350997.53
A34: Other Operating Expenses | B34: =B12*Assumptions!$B$20 -> 20430.984 | C34: =C12*Assumptions!$B$20 -> 19257.264 | D34: =D12*Assumptions!$B$20 -> 16344.727 | E34: =E12*Assumptions!$B$20 -> 15532.56 | F34: =F12*Assumptions!$B$20 -> 11589.845 | G34: =G12*Assumptions!$B$20 -> 15047.168 | H34: =H12*Assumptions!$B$20 -> 20430.984 | I34: =I12*Assumptions!$B$20 -> 19524.726 | ... M34: =M12*Assumptions!$B$20 -> 17979.266 | N34: =SUM(B34:M34) -> 197436.11
A35: Total Other Dept Expenses | B35: =SUM(B33:B34) -> 56752.734 | C35: =SUM(C33:C34) -> 53492.4 | D35: =SUM(D33:D34) -> 45402.019 | E35: =SUM(E33:E34) -> 43146 | F35: =SUM(F33:F34) -> 32194.013 | G35: =SUM(G33:G34) -> 41797.688 | H35: =SUM(H33:H34) -> 56752.734 | I35: =SUM(I33:I34) -> 54235.35 | ... M35: =SUM(M33:M34) -> 49942.406 | N35: =SUM(B35:M35) -> 548433.65
A36: Other Dept Profit | B36: =B12-B35 -> 34051.641 | C36: =C12-C35 -> 32095.44 | D36: =D12-D35 -> 27241.211 | E36: =E12-E35 -> 25887.6 | F36: =F12-F35 -> 19316.408 | G36: =G12-G35 -> 25078.612 | H36: =H12-H35 -> 34051.641 | I36: =I12-I35 -> 32541.21 | ... M36: =M12-M35 -> 29965.444 | N36: =SUM(B36:M36) -> 329060.19
A37: Other Dept Profit Margin | B37: =B36/B12 -> 0.375 | C37: =C36/C12 -> 0.375 | D37: =D36/D12 -> 0.375 | E37: =E36/E12 -> 0.375 | F37: =F36/F12 -> 0.375 | G37: =G36/G12 -> 0.375 | H37: =H36/H12 -> 0.375 | I37: =I36/I12 -> 0.375 | ... N37: =N36/N12 -> 0.375
A39: TOTAL DEPARTMENTAL
A40: Total Departmental Expenses | B40: =B20+B28+B35 -> 547096.36 | C40: =C20+C28+C35 -> 515666.74 | D40: =D20+D28+D35 -> 437675.46 | E40: =E20+E28+E35 -> 415927.44 | F40: =F20+F28+F35 -> 310350.28 | G40: =G20+G28+G35 -> 402929.71 | H40: =H20+H28+H35 -> 547096.36 | I40: =I20+I28+I35 -> 522828.77 | ... M40: =M20+M28+M35 -> 481444.8 | N40: =SUM(B40:M40) -> 5286900.4
A41: Total Departmental Profit | B41: =B14-B40 -> 814969.27 | C41: =C14-C40 -> 768150.86 | D41: =D14-D40 -> 651972.99 | E41: =E14-E40 -> 619576.56 | F41: =F14-F40 -> 462306.02 | G41: =G14-G40 -> 600214.79 | H41: =H14-H40 -> 814969.27 | I41: =I14-I40 -> 778819.63 | ... M41: =M14-M40 -> 717172.95 | N41: =SUM(B41:M41) -> 7875507.2
A42: Total Departmental Profit Margin | B42: =B41/B14 -> 0.59833333 | C42: =C41/C14 -> 0.59833333 | D42: =D41/D14 -> 0.59833333 | E42: =E41/E14 -> 0.59833333 | F42: =F41/F14 -> 0.59833333 | G42: =G41/G14 -> 0.59833333 | H42: =H41/H14 -> 0.59833333 | I42: =I41/I14 -> 0.59833333 | ... N42: =N41/N14 -> 0.59833333
A44: UNDISTRIBUTED OPERATING EXPENSES
A45: Administrative & General (A&G) | B45: =B14*Assumptions!$B$21 -> 122585.91 | C45: =C14*Assumptions!$B$21 -> 115543.58 | D45: =D14*Assumptions!$B$21 -> 98068.361 | E45: =E14*Assumptions!$B$21 -> 93195.36 | F45: =F14*Assumptions!$B$21 -> 69539.067 | G45: =G14*Assumptions!$B$21 -> 90283.005 | H45: =H14*Assumptions!$B$21 -> 122585.91 | I45: =I14*Assumptions!$B$21 -> 117148.36 | ... M45: =M14*Assumptions!$B$21 -> 107875.6 | N45: =SUM(B45:M45) -> 1184616.7
A46: Information & Telecommunications Systems (IT&S) | B46: =B14*Assumptions!$B$22 -> 20430.984 | C46: =C14*Assumptions!$B$22 -> 19257.264 | D46: =D14*Assumptions!$B$22 -> 16344.727 | E46: =E14*Assumptions!$B$22 -> 15532.56 | F46: =F14*Assumptions!$B$22 -> 11589.845 | G46: =G14*Assumptions!$B$22 -> 15047.167 | H46: =H14*Assumptions!$B$22 -> 20430.984 | I46: =I14*Assumptions!$B$22 -> 19524.726 | ... M46: =M14*Assumptions!$B$22 -> 17979.266 | N46: =SUM(B46:M46) -> 197436.11
A47: Sales & Marketing (S&M) | B47: =B14*Assumptions!$B$23 -> 108965.25 | C47: =C14*Assumptions!$B$23 -> 102705.41 | D47: =D14*Assumptions!$B$23 -> 87171.876 | E47: =E14*Assumptions!$B$23 -> 82840.32 | F47: =F14*Assumptions!$B$23 -> 61812.504 | G47: =G14*Assumptions!$B$23 -> 80251.56 | H47: =H14*Assumptions!$B$23 -> 108965.25 | I47: =I14*Assumptions!$B$23 -> 104131.87 | ... M47: =M14*Assumptions!$B$23 -> 95889.42 | N47: =SUM(B47:M47) -> 1052992.6
...

Sheet Dashboard
A1: Luxury Resort – Financial Performance Dashboard | P1: Month | Q1: Total Revenue | R1: GOP | S1: NOI
A2: Total Operating Revenue | D2: Occupancy | G2: ADR | J2: RevPAR | P2: Jan | Q2: ='Pro Forma P&L'!B14 -> 1362065.6 | R2: ='Pro Forma P&L'!B52 -> 426780.56 | S2: ='Pro Forma P&L'!B60 -> 310914.18
A3: ='Pro Forma P&L'!N14 -> 13162408 | D3: ='Pro Forma P&L'!N5 -> 0.65 | G3: ='Pro Forma P&L'!N7 -> 249.99824 | J3: ='Pro Forma P&L'!N10/'Pro Forma P&L'!N4 -> 162.49886 | P3: Feb | Q3: ='Pro Forma P&L'!C14 -> 1283817.6 | R3: ='Pro Forma P&L'!C52 -> 402262.85 | S3: ='Pro Forma P&L'!C60 -> 293052.76
P4: Mar | Q4: ='Pro Forma P&L'!D14 -> 1089648.5 | R4: ='Pro Forma P&L'!D52 -> 341423.18 | S4: ='Pro Forma P&L'!D60 -> 248730.42
P5: Apr | Q5: ='Pro Forma P&L'!E14 -> 1035504 | R5: ='Pro Forma P&L'!E52 -> 324457.92 | S5: ='Pro Forma P&L'!E60 -> 236371.05
A6: Gross Operating Profit (GOP) | D6: GOP Margin | G6: NOI | J6: NOI Margin | P6: May | Q6: ='Pro Forma P&L'!F14 -> 772656.3 | R6: ='Pro Forma P&L'!F52 -> 242098.97 | S6: ='Pro Forma P&L'!F60 -> 176371.68
A7: ='Pro Forma P&L'!N52 -> 4124221 | D7: ='Pro Forma P&L'!N53 -> 0.31333333 | G7: ='Pro Forma P&L'!N60 -> 3004538.9 | J7: ='Pro Forma P&L'!N61 -> 0.22826667 | P7: Jun | Q7: ='Pro Forma P&L'!G14 -> 1003144.5 | R7: ='Pro Forma P&L'!G52 -> 314318.61 | S7: ='Pro Forma P&L'!G60 -> 228984.45
P8: Jul | Q8: ='Pro Forma P&L'!H14 -> 1362065.6 | R8: ='Pro Forma P&L'!H52 -> 426780.56 | S8: ='Pro Forma P&L'!H60 -> 310914.18
P9: Aug | Q9: ='Pro Forma P&L'!I14 -> 1301648.4 | R9: ='Pro Forma P&L'!I52 -> 407849.83 | S9: ='Pro Forma P&L'!I60 -> 297122.94
A10: Monthly profitability trend | H10: Occupancy trend | P10: Sep | Q10: ='Pro Forma P&L'!J14 -> 772656.3 | R10: ='Pro Forma P&L'!J52 -> 242098.97 | S10: ='Pro Forma P&L'!J60 -> 176371.68
P11: Oct | Q11: ='Pro Forma P&L'!K14 -> 835423.88 | R11: ='Pro Forma P&L'!K52 -> 261766.15 | S11: ='Pro Forma P&L'!K60 -> 190699.42
P12: Nov | Q12: ='Pro Forma P&L'!L14 -> 1145159.1 | R12: ='Pro Forma P&L'!L52 -> 358816.52 | S12: ='Pro Forma P&L'!L60 -> 261401.65
P13: Dec | Q13: ='Pro Forma P&L'!M14 -> 1198617.8 | R13: ='Pro Forma P&L'!M52 -> 375566.89 | S13: ='Pro Forma P&L'!M60 -> 273604.48
P16: Month | Q16: Occupancy | T16: Month | U16: ADR | V16: RevPAR
P17: Jan | Q17: ='Pro Forma P&L'!B5 -> 0.75 | T17: Jan | U17: ='Pro Forma P&L'!B7 -> 269.05 | V17: ='Pro Forma P&L'!B10/'Pro Forma P&L'!B4 -> 201.7875
P18: Feb | Q18: ='Pro Forma P&L'!C5 -> 0.72 | T18: Feb | U18: ='Pro Forma P&L'!C7 -> 264.16 | V18: ='Pro Forma P&L'!C10/'Pro Forma P&L'!C4 -> 190.1952
P19: Mar | Q19: ='Pro Forma P&L'!D5 -> 0.66 | T19: Mar | U19: ='Pro Forma P&L'!D7 -> 244.59 | V19: ='Pro Forma P&L'!D10/'Pro Forma P&L'!D4 -> 161.4294
P20: Apr | Q20: ='Pro Forma P&L'!E5 -> 0.64 | T20: Apr | U20: ='Pro Forma P&L'!E7 -> 239.7 | V20: ='Pro Forma P&L'!E10/'Pro Forma P&L'!E4 -> 153.408
P21: May | Q21: ='Pro Forma P&L'!F5 -> 0.52 | T21: May | U21: ='Pro Forma P&L'!F7 -> 220.13 | V21: ='Pro Forma P&L'!F10/'Pro Forma P&L'!F4 -> 114.4676
P22: Jun | Q22: ='Pro Forma P&L'!G5 -> 0.62 | T22: Jun | U22: ='Pro Forma P&L'!G7 -> 239.7 | V22: ='Pro Forma P&L'!G10/'Pro Forma P&L'!G4 -> 148.614
P23: Jul | Q23: ='Pro Forma P&L'!H5 -> 0.75 | T23: Jul | U23: ='Pro Forma P&L'!H7 -> 269.05 | V23: ='Pro Forma P&L'!H10/'Pro Forma P&L'!H4 -> 201.7875
P24: Aug | Q24: ='Pro Forma P&L'!I5 -> 0.73 | T24: Aug | U24: ='Pro Forma P&L'!I7 -> 264.16 | V24: ='Pro Forma P&L'!I10/'Pro Forma P&L'!I4 -> 192.8368
P25: Sep | Q25: ='Pro Forma P&L'!J5 -> 0.52 | T25: Sep | U25: ='Pro Forma P&L'!J7 -> 220.13 | V25: ='Pro Forma P&L'!J10/'Pro Forma P&L'!J4 -> 114.4676
P26: Oct | Q26: ='Pro Forma P&L'!K5 -> 0.55 | T26: Oct | U26: ='Pro Forma P&L'!K7 -> 225.03 | V26: ='Pro Forma P&L'!K10/'Pro Forma P&L'!K4 -> 123.7665
A27: ADR and RevPAR trend | H27: Annual revenue mix | P27: Nov | Q27: ='Pro Forma P&L'!L5 -> 0.68 | T27: Nov | U27: ='Pro Forma P&L'!L7 -> 249.49 | V27: ='Pro Forma P&L'!L10/'Pro Forma P&L'!L4 -> 169.6532
P28: Dec | Q28: ='Pro Forma P&L'!M5 -> 0.66 | T28: Dec | U28: ='Pro Forma P&L'!M7 -> 269.05 | V28: ='Pro Forma P&L'!M10/'Pro Forma P&L'!M4 -> 177.573
P31: Revenue Stream | Q31: Annual Revenue
P32: Rooms | Q32: ='Pro Forma P&L'!N10 -> 8774938.4
P33: Food & Beverage | Q33: ='Pro Forma P&L'!N11 -> 3509975.3
P34: Spa / Other | Q34: ='Pro Forma P&L'!N12 -> 877493.84
A44: Annual profitability bridge | H44: Departmental performance
A45: Metric | B45: Annual Value | C45: % of Total Revenue | H45: Department | I45: Revenue | J45: Expenses | K45: Profit | L45: Margin
A46: Total Operating Revenue | B46: ='Pro Forma P&L'!N14 -> 13162408 | C46: =B46/B46 -> 1 | H46: Rooms | I46: ='Pro Forma P&L'!N10 -> 8774938.4 | J46: ='Pro Forma P&L'!N20 -> 2018235.8 | K46: ='Pro Forma P&L'!N21 -> 6756702.5 | L46: ='Pro Forma P&L'!N22 -> 0.77
A47: Total Departmental Expenses | B47: ='Pro Forma P&L'!N40 -> 5286900.4 | C47: =B47/$B$46 -> 0.40166667 | H47: Food & Beverage | I47: ='Pro Forma P&L'!N11 -> 3509975.3 | J47: ='Pro Forma P&L'!N28 -> 2720230.9 | K47: ='Pro Forma P&L'!N29 -> 789744.45 | L47: ='Pro Forma P&L'!N30 -> 0.225
A48: Total Departmental Profit | B48: ='Pro Forma P&L'!N41 -> 7875507.2 | C48: =B48/$B$46 -> 0.59833333 | H48: Spa / Other | I48: ='Pro Forma P&L'!N12 -> 877493.84 | J48: ='Pro Forma P&L'!N35 -> 548433.65 | K48: ='Pro Forma P&L'!N36 -> 329060.19 | L48: ='Pro Forma P&L'!N37 -> 0.375
A49: Undistributed Operating Expenses | B49: ='Pro Forma P&L'!N50 -> 3751286.1 | C49: =B49/$B$46 -> 0.285 | H49: Total operated departments | I49: ='Pro Forma P&L'!N10+'Pro Forma P&L'!N11+'Pro Forma P&L'!N12 -> 13162408 | J49: ='Pro Forma P&L'!N40 -> 5286900.4 | K49: ='Pro Forma P&L'!N41 -> 7875507.2 | L49: ='Pro Forma P&L'!N42 -> 0.59833333
A50: Gross Operating Profit (GOP) | B50: ='Pro Forma P&L'!N52 -> 4124221 | C50: =B50/$B$46 -> 0.31333333
A51: Management Fees | B51: ='Pro Forma P&L'!N56+'Pro Forma P&L'!N57 -> 593185.83 | C51: =B51/$B$46 -> 0.045066667
A52: FF&E Replacement Reserve | B52: ='Pro Forma P&L'!N58 -> 526496.3 | C52: =B52/$B$46 -> 0.04
A53: NOI | B53: ='Pro Forma P&L'!N60 -> 3004538.9 | C53: =B53/$B$46 -> 0.22826667
