Workbook

Sheet Tóm tắt profile
A1: Thực hành phát triển bền vững theo từng khía cạnh của các khu nghỉ dưỡng
A2: Khu nghỉ dưỡng | B2: Tóm tắt về minh chứng đã công bố | C2: Năng lượng & Khí hậu | D2: Nước | E2: Chất thải & Nhựa | F2: Thực phẩm & Thu mua | G2: Đa dạng sinh học & Hệ sinh thái | H2: Cộng đồng & Con người | I2: Văn hóa & Di sản | J2: Gắn kết khách hàng | K2: Lưu ý
A3: Six Senses Ninh Van Bay | B3: 8/8 khía cạnh; 5 khía cạnh có dữ liệu định lượng; có nguồn đối chiếu bên ngoài ở biodiversity/community. | C3: Điện mặt trời; 739.782 kWh năm 2025, khoảng 26–28% nhu cầu điện. Chưa thấy KPI cường độ năng lượng công khai. | D3: Tiết kiệm nước trong vận hành; chưa thấy KPI nước/khách hoặc phòng có khách công khai. | E3: Chai thủy tinh tái sử dụng; 156.288 chai nhựa tránh dùng; ủ phân hữu cơ và thu gom rác cộng đồng. | F3: 3 vườn hữu cơ; 13.849 kg nông sản hữu cơ; có định hướng thu mua có trách nhiệm nhưng chưa thấy tỷ lệ địa phương. | G3: Bảo tồn voọc, phục hồi san hô và rừng ngập mặn; GreenViet tham gia theo dõi đa dạng sinh học. | H3: Hỗ trợ giáo dục, nước sạch, đèn năng lượng mặt trời và đào tạo bảo tồn cho nhân viên/cộng đồng. | I3: Earth Lab và Langur Lounge giới thiệu văn hóa địa phương gắn với thiên nhiên và bảo tồn. | J3: Langur Discovery, Nature Hike, Langur Talk, Flora Walk và các hoạt động tìm hiểu thiên nhiên. | K3: Nhiều số liệu là đầu ra; ít KPI chuẩn hóa về năng lượng/nước/chất thải.
A4: InterContinental Danang Sun Peninsula Resort | B4: 8/8 khía cạnh; nhiều thực hành định tính; có Green Globe. | C4: Theo dõi năng lượng và áp dụng biện pháp tiết kiệm; chưa thấy KPI cường độ hiện tại. | D4: Thiết bị tiết kiệm nước, tái sử dụng và xử lý nước thải; có hệ thống quản lý nước trong vận hành. | E4: Chai thủy tinh, phân loại và tái chế; xử lý rác hữu cơ và theo dõi chất thải. | F4: Thu mua địa phương và vật liệu ưu tiên môi trường; tránh các loài dễ tổn thương. | G4: Bảo tồn linh trưởng, cầu cho động vật di chuyển và hỗ trợ sinh cảnh Sơn Trà. | H4: Lao động địa phương, đào tạo nhân viên, hợp tác với trường đào tạo và các hoạt động cộng đồng. | I4: Nghệ thuật, kiến trúc và câu chuyện địa phương được đưa vào thiết kế và trải nghiệm. | J4: Resident naturalist, Nature Expeditions, Ecowalks và Primate Appreciation Month. | K4: Ít KPI định lượng cấp property về cường độ tài nguyên.
A5: Banyan Tree Lang Co | B5: 4/8 khía cạnh có bằng chứng hiện tại trong ma trận, có chứng nhận | C5: Chưa thấy KPI hiện tại riêng cho Banyan Tree Lang Co; một số thông tin môi trường là cấp Laguna Lang Co. | D5: Xử lý nước thải và nguồn nước thay thế ở cấp khu phức hợp; không gán trực tiếp thành KPI riêng của resort. | E5: Đóng chai thủy tinh và ủ phân ở cấp khu phức hợp; chưa có KPI hiện tại riêng của resort. | F5: Chưa thấy KPI hiện tại rõ về tỷ lệ thu mua địa phương hoặc thu mua có trách nhiệm. | G5: Birdwatching và chương trình Signature Birds; bằng chứng hiện tại về KPI sinh thái còn hạn chế. | H5: Đào tạo nghề, hỗ trợ cộng đồng và cơ hội việc làm cho nghệ nhân/người khuyết tật. | I5: Thủ công địa phương và câu chuyện văn hóa được đưa vào sản phẩm và trải nghiệm. | J5: Workshop thủ công, Stay for Good và birdwatching; một số hoạt động kết nối trực tiếp nghệ nhân với khách. | K5: Không gán KPI Laguna integrated resort thành KPI của Banyan Tree property.
A6: Topas Ecolodge | B6: 7/8 khía cạnh; nổi bật về địa gắn kết địa phương | C6: Vận hành tiết kiệm năng lượng và sử dụng nguồn tái tạo; chưa có KPI hiệu suất công khai rõ. | D6: Thu gom nước mưa, tái sử dụng nước xám và xử lý nước thải bằng vùng đất ngập nước nhân tạo. | E6: Loại bỏ nhựa dùng một lần; tái sử dụng chai thủy tinh; đưa chất thải thực phẩm cho hộ dân/nông dân địa phương. | F6: >80% thực phẩm và vật tư nhà hàng mua trực tiếp từ nông trại địa phương. | G6: Làm việc trong cảnh quan Hoàng Liên và có các thực hành bảo vệ môi trường; chưa thấy KPI đa dạng sinh học cụ thể. | H6: >98% nhân viên là người dân tộc thiểu số từ các bản xung quanh; hỗ trợ nghệ nhân và đào tạo nghề. | I6: Nghề thủ công, kiến trúc, ẩm thực và câu chuyện địa phương. | J6: Workshop văn hóa, Green Leaf Initiative và hoạt động bảo vệ cảnh quan có sự tham gia của khách. | K6: Ít KPI hiệu suất chuẩn hóa; ASEAN Green Hotel là ghi nhận, không phải audit KPI.
A7: The Westin Resort & Spa Cam Ranh | B7: 8/8 khía cạnh, một vài KPI được chuẩn hóa | C7: Mục tiêu giảm 10% tác động liên quan năng lượng/nước/chất thải vào cuối 2026; đạt 3% đến cuối 2025; 83,5 kg CO₂e/phòng có khách. | D7: 4.539,37 lít nước/phòng có khách. | E7: Chuyển sang chai thủy tinh, tránh hơn 81.000 chai nhựa; có tái chế tại phòng khách. | F7: Thu mua protein và hải sản có trách nhiệm; chưa công bố tỷ lệ. | G7: Cam kết bảo vệ đa dạng sinh học nhưng chưa có KPI về loài hoặc sinh cảnh. | H7: Gây quỹ Road to Give; 1.000 USD năm 2025 và mục tiêu 2.000 USD năm 2026 cho hỗ trợ cộng đồng/giáo dục. | I7: Vật liệu tự nhiên, mái xanh và thiết kế gợi liên hệ tới làng chài địa phương. | J7: Khuyến khích khách tiết kiệm nước, năng lượng, giảm rác và tham gia đóng góp cộng đồng. | K7: Trạng thái Travelife mới được doanh nghiệp công bố; primary directory chưa được truy xuất trong đợt rà.
A8: Six Senses Con Dao | B8: 8/8 khía cạnh, nhiều dữ liệu định lượng cấp cơ sở | C8: Thông gió tự nhiên, vật liệu tái chế và sử dụng một phần năng lượng mặt trời; chưa có KPI cường độ hiện tại. | D8: Nước thải đã xử lý được tái sử dụng cho vườn và cảnh quan. | E8: 97.656 chai nhựa tránh dùng; 305 kg nhựa chuyển hướng khỏi chôn lấp; 1.763 kg rác bãi biển thu gom. | F8: Vườn hữu cơ khoảng 3.000 m²; 5.641,7 kg rau tươi thu hoạch năm 2025. | G8: Bảo tồn rùa xanh; 3.818 rùa con nở và được thả về biển năm 2025, phối hợp với Vườn quốc gia Côn Đảo. | H8: Water for All với 12 máy lọc nước và 3.879 người hưởng lợi; 84 giờ dạy tiếng Anh cho cộng đồng. | I8: Thiết kế lấy cảm hứng từ làng chài Côn Đảo. | J8: Trải nghiệm thả rùa, Earth Lab, tour phát triển bền vững và hoạt động tại vườn. | K8: Có GSTC/Control Union; phần lớn KPI property vẫn là số liệu doanh nghiệp tự công bố
A9: Mango Bay Phu Quoc | B9: 6/8 khía cạnh; nổi bật về vân hành sinh thái và tích hợp địa phương | C9: Thông gió tự nhiên, nước nóng năng lượng mặt trời, ánh sáng tự nhiên và thiết bị tiết kiệm năng lượng. | D9: Bồn cầu lưu lượng thấp, xử lý nước xám bằng bãi lọc trồng cây và tái sử dụng cho vườn/vườn ươm. | E9: Mua hàng số lượng lớn, tái chế giấy/kính và tái sử dụng chất thải hữu cơ. | F9: >85% hoạt động mua hàng từ nhà cung cấp địa phương. | G9: Phối hợp với Wildlife At Risk và Vườn quốc gia Phú Quốc; khảo sát đa dạng sinh học và phục hồi cây bản địa. | H9: >80% nhân viên địa phương. | I9: Thợ thủ công và vật liệu địa phương/recycled materials gắn với bối cảnh Phú Quốc. | J9: Trải nghiệm địa phương; bằng chứng hiện tại về mức tham gia hoặc tác động lên khách còn hạn chế. | K9: Một số bằng chứng biodiversity mang tính lịch sử; chưa tìm thấy current third-party certification.
A10: Avana Retreat | B10: 6/8 khía cạnh; nổi bật về đa dạng sinh học, cộng đồng và văn hóa | C10: Thực hành giảm tác động trong vận hành; chưa thấy KPI hiện tại rõ về năng lượng. | D10: Thực hành tiết kiệm nước; chưa thấy KPI hiện tại rõ về cường độ nước. | E10: Giảm hoặc loại bỏ nhựa dùng một lần; chưa có số liệu giảm định lượng rõ. | F10: Vườn hữu cơ gắn với hoạt động ẩm thực; chưa có tỷ lệ thu mua địa phương định lượng. | G10: Phục hồi rừng; gần 12.000 cây đến 2025; 151 loài; BioScore tăng 24,6% theo đối tác bên ngoài. | H10: 98% nhân viên địa phương; đội ngũ cảnh quan địa phương và hoạt động với nghệ nhân. | I10: Tri thức và văn hóa Thái, H’Mông, Mường được đưa vào kiến trúc, nghề thủ công và hoạt động trải nghiệm. | J10: Thăm vườn, thu hoạch, nấu ăn và workshop văn hóa/thủ công. | K10: Khoảng trống công khai về energy/water; có chênh lệch 90% và 98% local staff giữa nguồn cũ/mới.
A11: Silk Sense Hoi An River Resort | B11: 8/8 khía cạnh; báo cáo vận hành chi tiết | C11: 2,81 kWh/khách năm 2025; tổng điện giảm 12,4%. | D11: Nước giảm từ 0,71 xuống 0,68 m³/khách giai đoạn 2024–2025. | E11: 1.536 kg rác chôn lấp năm 2025; gần 24 tấn rác hữu cơ xử lý bằng Waste2Green năm 2024; mở rộng loại bỏ nhựa dùng một lần. | F11: Tỷ lệ nhà cung cấp địa phương tăng từ 58% lên 80% năm 2025. | G11: Cây bản địa, mặt nước, không gian xanh và giáo dục đa dạng sinh học; chưa có KPI loài. | H11: 95% nhân viên địa phương; gây quỹ 70 triệu đồng hỗ trợ vùng lũ. | I11: Thủ công, nguyên liệu và hoạt động văn hóa địa phương. | J11: Vườn hữu cơ, lớp nấu ăn và thông tin đa dạng sinh học trong hành trình khách. | K11: Một số số liệu diesel trong report không nhất quán nên đã loại khỏi comparison.
A12: Legacy Mekong | B12: 4/8 khía cạnh; chủ yếu là dữ liệu lịch sử | C12: Hệ thống điện mặt trời 500 kWp là dữ liệu lịch sử; chưa có KPI hiện tại được xác minh. | D12: Chưa tìm thấy KPI hiện tại đủ cụ thể. | E12: Chưa tìm thấy KPI hiện tại đủ cụ thể. | F12: Nguyên liệu địa phương và ẩm thực Mekong; chưa có tỷ lệ thu mua hiện tại. | G12: Bảo tồn cây trưởng thành và cảnh quan xanh; chưa có KPI đa dạng sinh học hiện tại. | H12: Chưa tìm thấy chương trình cộng đồng hiện tại có số liệu đủ cụ thể. | I12: Ẩm thực, vật liệu, thiết kế và trải nghiệm gắn với bản sắc Mekong. | J12: Các trải nghiệm hiện tại có trồng xương rồng, workshop, picnic, ẩm thực và hoạt động gắn với địa phương. | K12: Chưa tìm thấy KPI cụ thể về năng lượng, nước, chất thải, cộng đồng hoặc chứng nhận phát triển bền vững ở cấp cơ sở.

Sheet Trọng tâm triển khai
A1: Trọng tâm triển khai của các khu nghỉ dưỡng
A2: Khu nghỉ dưỡng | B2: Trọng tâm triển khai | C2: Các hoạt động nổi bật
A3: Six Senses Ninh Van Bay | B3: Bảo tồn & phục hồi hệ sinh thái; quản lý tài nguyên; cộng đồng & giáo dục | C3: Có hệ thống năng lượng mặt trời, vườn hữu cơ và quản lý chất thải; đồng thời có bảo tồn voọc, san hô, rừng ngập mặn và nhiều chương trình cộng đồng. Earth Lab kết nối các hoạt động này với khách.
A4: InterContinental Danang Sun Peninsula Resort | B4: Bảo tồn thiên nhiên; giáo dục & trải nghiệm thiên nhiên; quản lý vận hành | C4: Bảo tồn linh trưởng được thể hiện qua cầu cho khỉ, trồng cây, naturalist và các chương trình giáo dục. Chủ đề này còn được đưa vào nhiều hoạt động dành cho khách như Green Hub, Kids activities, yoga và F&B.
A5: Banyan Tree Lang Co | B5: Cộng đồng & hòa nhập; văn hóa địa phương; đa dạng sinh học & trải nghiệm | C5: Hỗ trợ đào tạo và cơ hội việc làm cho cộng đồng; thủ công địa phương; hoạt động với nghệ nhân và người khuyết tật; birdwatching và trải nghiệm văn hóa.
A6: Topas Ecolodge | B6: Cộng đồng địa phương; thu mua địa phương; vận hành tiết kiệm tài nguyên | C6: Lao động địa phương, thu mua từ nông hộ, nghề thủ công và trải nghiệm văn hóa; các biện pháp tiết kiệm tài nguyên và giảm nhựa.
A7: The Westin Resort & Spa Cam Ranh | B7: Đo lường hiệu suất môi trường; giảm tác động tài nguyên; cộng đồng | C7: Có mục tiêu giảm 10% phát thải liên quan đến năng lượng, nước và chất thải đến cuối 2026, đã báo cáo mức giảm 3% đến cuối 2025; đồng thời công bố carbon/water footprint và các hoạt động cộng đồng.
A8: Six Senses Con Dao | B8: Bảo tồn loài gắn với trải nghiệm khách; quản lý tài nguyên & chất thải; cộng đồng & trải nghiệm | C8: Bảo tồn rùa là chương trình rất rõ với Vườn quốc gia Côn Đảo; song song có vườn hữu cơ, giảm nhựa, 2R Station, Water for All, lớp tiếng Anh và các hoạt động để khách tham gia.
A9: Mango Bay Phu Quoc | B9: Vận hành ít tác động; cộng đồng & kinh tế địa phương; bảo tồn thiên nhiên | C9: Thông gió tự nhiên, nước nóng năng lượng mặt trời, xử lý và tái sử dụng nước; giảm chất thải; thu mua và lao động địa phương; hỗ trợ bảo tồn Phú Quốc.
A10: Avana Retreat | B10: Phục hồi hệ sinh thái; cộng đồng địa phương; văn hóa & kiến trúc bản địa | C10: Có chương trình phục hồi rừng, gần 12.000 cây đến 2025 và BioScore tăng 24,6%; 98% nhân viên địa phương và nghệ nhân Thái, H’Mông, Mường tham gia vào kiến trúc, nghề thủ công và trải nghiệm.
A11: Silk Sense Hoi An River Resort | B11: Đo lường hiệu suất vận hành; thu mua địa phương; tích hợp sustainability vào trải nghiệm | C11: Theo dõi điện, nước, chất thải và tỷ lệ nhà cung cấp địa phương; vườn hữu cơ; giảm nhựa; hoạt động văn hóa và giáo dục đa dạng sinh học.
A12: Legacy Mekong | B12: Bản sắc địa phương & trải nghiệm; ẩm thực địa phương; khung quản lý cấp tập đoàn | C12: Ẩm thực Mekong, vật liệu và thiết kế gắn với địa phương, cùng các trải nghiệm liên quan đến đời sống và cảnh quan Mekong.

Sheet Mức độ xác minh dữ kiện
A1: Mức độ xác minh về dữ kiện được công khai
A2: Mã | B2: Ý nghĩa | C2: Cách hiểu | D2: Khu nghỉ dưỡng | E2: Năng lượng & Khí hậu | F2: Nước | G2: Chất thải & Nhựa | H2: Thực phẩm & Thu mua | I2: Đa dạng sinh học & Hệ sinh thái | J2: Cộng đồng & Con người | K2: Văn hóa & Di sản | L2: Gắn kết khách hàng | M2: Quản lý / tích hợp
A3: NB+ĐL | B3: Nguồn bên ngoài + dữ liệu định lượng | C3: Có nguồn bên ngoài xác nhận/đối chiếu và có chỉ số định lượng | D3: Six Senses Ninh Van Bay | E3: ĐL | F3: ĐT | G3: ĐL | H3: ĐL | I3: NB+ĐL | J3: NB+ĐL | K3: ĐT | L3: NB | M3: Có tên trong danh bạ GSTC; Control Union (GSTC-I), chu kỳ 2024–2027. Có thêm ghi nhận HICAP 2024.
A4: NB | B4: Nguồn bên ngoài | C4: Có chứng nhận/đối tác/đánh giá bên ngoài nhưng không có chỉ số định lượng phù hợp ở ô này | D4: InterContinental Danang Sun Peninsula Resort | E4: ĐT | F4: NB | G4: ĐT | H4: ĐT | I4: ĐL | J4: ĐT | K4: ĐT | L4: NB | M4: Green Globe xác nhận chứng nhận công khai; khu nghỉ dưỡng cũng công bố Kế hoạch Quản lý Bền vững 2026–2027.
A5: ĐL | B5: Doanh nghiệp công bố định lượng | C5: Có số liệu/chỉ số do doanh nghiệp tự công bố | D5: Banyan Tree Lang Co | E5: TT | F5: BC | G5: BC | H5: TT | I5: ĐL | J5: ĐT | K5: ĐT | L5: ĐT | M5: Có tên trong danh bạ GSTC; Control Union (GSTC-I), chu kỳ 2025–2028. EarthCheck Gold 2022 chỉ dùng như bối cảnh lịch sử/cấp khu phức hợp.
A6: ĐT | B6: Doanh nghiệp công bố định tính | C6: Có thực hành/tuyên bố nhưng chưa có số liệu cụ thể | D6: Topas Ecolodge | E6: ĐT | F6: ĐT | G6: ĐT | H6: ĐL | I6: TT | J6: ĐL | K6: ĐT | L6: ĐT | M6: Được xác nhận nhận Giải Khách sạn Xanh ASEAN 2026; xem đây là ghi nhận độc lập, không phải kiểm toán chứng nhận toàn bộ chỉ số.
A7: TT | B7: Thiếu minh chứng cụ thể | C7: Chưa tìm thấy bằng chứng ở cấp cơ sở đủ cụ thể trong phạm vi nguồn đã rà | D7: The Westin Resort & Spa Cam Ranh | E7: ĐL | F7: ĐL | G7: ĐL | H7: ĐT | I7: ĐT | J7: ĐL | K7: ĐT | L7: ĐT | M7: Marriott công bố trạng thái Travelife Certified; trong đợt rà soát công khai này chưa truy xuất được hồ sơ gốc từ danh bạ Travelife.
A8: BC | B8: Bối cảnh cấp khu phức hợp | C8: Thông tin thuộc khu nghỉ dưỡng tích hợp/điểm đến, không thể quy hoàn toàn cho cơ sở | D8: Six Senses Con Dao | E8: ĐT | F8: ĐT | G8: ĐL | H8: ĐL | I8: ĐL | J8: ĐL | K8: ĐT | L8: ĐT | M8: Có tên trong danh bạ GSTC; Control Union (GSTC-I), chu kỳ 2024–2027, mã GSTC HACU240332-1.
A9: LS | B9: Dữ liệu lịch sử | C9: Có bằng chứng trong quá khứ nhưng chưa xác nhận là hiện trạng năm 2026 | D9: Mango Bay Phu Quoc | E9: ĐT | F9: ĐT | G9: ĐT | H9: ĐL | I9: LS | J9: ĐL | K9: ĐT | L9: TT | M9: Chưa tìm thấy chứng nhận phát triển bền vững bên thứ ba còn hiệu lực trong các nguồn công khai đã rà.
D10: Avana Retreat | E10: TT | F10: TT | G10: ĐT | H10: ĐT | I10: NB | J10: ĐL | K10: ĐT | L10: ĐT | M10: Có đánh giá đa dạng sinh học/văn hóa sinh học từ Guardians of Earth; đây là đánh giá bên ngoài, không phải chứng nhận phát triển bền vững của khách sạn.
D11: Silk Sense Hoi An River Resort | E11: ĐL | F11: ĐL | G11: ĐL | H11: ĐL | I11: ĐT | J11: ĐL | K11: ĐT | L11: ĐT | M11: Khu nghỉ dưỡng công bố Travelife Gold và có Báo cáo Phát triển Bền vững chi tiết; chưa truy xuất được hồ sơ gốc từ danh bạ Travelife trong đợt rà này.
D12: Legacy Mekong | E12: LS | F12: TT | G12: TT | H12: ĐT | I12: NB | J12: TT | K12: NB | L12: ĐT | M12: Từ cuối năm 2025, khu nghỉ dưỡng thuộc Autograph Collection của Marriott và nằm trong định hướng quản lý phát triển bền vững cấp tập đoàn Serve 360. Tuy nhiên, chưa tìm thấy chứng nhận phát triển bền vững hiện hành hoặc bộ KPI môi trường – xã hội được công bố riêng ở cấp khu nghỉ dưỡng.
A23: Mức độ tiến triển của hoạt động | B23: Core & supporting records
A24: Thực hành | B24: 53
A25: Đầu ra | B25: 44
A26: Tạo ra thay đổi | B26: 10
A27: Cam kết | B27: 1

Sheet Dimensions coverage
A1: Tổng hợp minh chứng theo 8 khía cạnh
A2: Các khía cạnh | B2: Số khu nghỉ dưỡng có bằng chứng hiện tại | C2: Có dữ liệu định lượng | D2: Có nguồn bên ngoài | E2: Chỉ có bằng chứng định tính | F2: Thiếu minh chứng cụ thể | G2: Chỉ có bối cảnh/lịch sử
A3: Năng lượng & Khí hậu | B3: =COUNTIF('Mức độ xác minh dữ kiện'!E$3:E$12,"NB+ĐL")+COUNTIF('Mức độ xác minh dữ kiện'!E$3:E$12,"NB")+COUNTIF('Mức độ xác minh dữ kiện'!E$3:E$12,"ĐL")+COUNTIF('Mức độ xác minh dữ kiện'!E$3:E$12,"ĐT") -> 7 | C3: =COUNTIF('Mức độ xác minh dữ kiện'!E$3:E$12,"NB+ĐL")+COUNTIF('Mức độ xác minh dữ kiện'!E$3:E$12,"ĐL") -> 3 | D3: =COUNTIF('Mức độ xác minh dữ kiện'!E$3:E$12,"NB+ĐL")+COUNTIF('Mức độ xác minh dữ kiện'!E$3:E$12,"NB") -> 0 | E3: =COUNTIF('Mức độ xác minh dữ kiện'!E$3:E$12,"ĐT") -> 4 | F3: =COUNTIF('Mức độ xác minh dữ kiện'!E$3:E$12,"TT") -> 2 | G3: =COUNTIF('Mức độ xác minh dữ kiện'!E$3:E$12,"BC")+COUNTIF('Mức độ xác minh dữ kiện'!E$3:E$12,"LS") -> 1
A4: Nước | B4: =COUNTIF('Mức độ xác minh dữ kiện'!F$3:F$12,"NB+ĐL")+COUNTIF('Mức độ xác minh dữ kiện'!F$3:F$12,"NB")+COUNTIF('Mức độ xác minh dữ kiện'!F$3:F$12,"ĐL")+COUNTIF('Mức độ xác minh dữ kiện'!F$3:F$12,"ĐT") -> 7 | C4: =COUNTIF('Mức độ xác minh dữ kiện'!F$3:F$12,"NB+ĐL")+COUNTIF('Mức độ xác minh dữ kiện'!F$3:F$12,"ĐL") -> 2 | D4: =COUNTIF('Mức độ xác minh dữ kiện'!F$3:F$12,"NB+ĐL")+COUNTIF('Mức độ xác minh dữ kiện'!F$3:F$12,"NB") -> 1 | E4: =COUNTIF('Mức độ xác minh dữ kiện'!F$3:F$12,"ĐT") -> 4 | F4: =COUNTIF('Mức độ xác minh dữ kiện'!F$3:F$12,"TT") -> 2 | G4: =COUNTIF('Mức độ xác minh dữ kiện'!F$3:F$12,"BC")+COUNTIF('Mức độ xác minh dữ kiện'!F$3:F$12,"LS") -> 1
A5: Chất thải & Nhựa | B5: =COUNTIF('Mức độ xác minh dữ kiện'!G$3:G$12,"NB+ĐL")+COUNTIF('Mức độ xác minh dữ kiện'!G$3:G$12,"NB")+COUNTIF('Mức độ xác minh dữ kiện'!G$3:G$12,"ĐL")+COUNTIF('Mức độ xác minh dữ kiện'!G$3:G$12,"ĐT") -> 8 | C5: =COUNTIF('Mức độ xác minh dữ kiện'!G$3:G$12,"NB+ĐL")+COUNTIF('Mức độ xác minh dữ kiện'!G$3:G$12,"ĐL") -> 4 | D5: =COUNTIF('Mức độ xác minh dữ kiện'!G$3:G$12,"NB+ĐL")+COUNTIF('Mức độ xác minh dữ kiện'!G$3:G$12,"NB") -> 0 | E5: =COUNTIF('Mức độ xác minh dữ kiện'!G$3:G$12,"ĐT") -> 4 | F5: =COUNTIF('Mức độ xác minh dữ kiện'!G$3:G$12,"TT") -> 1 | G5: =COUNTIF('Mức độ xác minh dữ kiện'!G$3:G$12,"BC")+COUNTIF('Mức độ xác minh dữ kiện'!G$3:G$12,"LS") -> 1
A6: Thực phẩm & Thu mua | B6: =COUNTIF('Mức độ xác minh dữ kiện'!H$3:H$12,"NB+ĐL")+COUNTIF('Mức độ xác minh dữ kiện'!H$3:H$12,"NB")+COUNTIF('Mức độ xác minh dữ kiện'!H$3:H$12,"ĐL")+COUNTIF('Mức độ xác minh dữ kiện'!H$3:H$12,"ĐT") -> 9 | C6: =COUNTIF('Mức độ xác minh dữ kiện'!H$3:H$12,"NB+ĐL")+COUNTIF('Mức độ xác minh dữ kiện'!H$3:H$12,"ĐL") -> 5 | D6: =COUNTIF('Mức độ xác minh dữ kiện'!H$3:H$12,"NB+ĐL")+COUNTIF('Mức độ xác minh dữ kiện'!H$3:H$12,"NB") -> 0 | E6: =COUNTIF('Mức độ xác minh dữ kiện'!H$3:H$12,"ĐT") -> 4 | F6: =COUNTIF('Mức độ xác minh dữ kiện'!H$3:H$12,"TT") -> 1 | G6: =COUNTIF('Mức độ xác minh dữ kiện'!H$3:H$12,"BC")+COUNTIF('Mức độ xác minh dữ kiện'!H$3:H$12,"LS") -> 0
A7: Đa dạng sinh học & Hệ sinh thái | B7: =COUNTIF('Mức độ xác minh dữ kiện'!I$3:I$12,"NB+ĐL")+COUNTIF('Mức độ xác minh dữ kiện'!I$3:I$12,"NB")+COUNTIF('Mức độ xác minh dữ kiện'!I$3:I$12,"ĐL")+COUNTIF('Mức độ xác minh dữ kiện'!I$3:I$12,"ĐT") -> 8 | C7: =COUNTIF('Mức độ xác minh dữ kiện'!I$3:I$12,"NB+ĐL")+COUNTIF('Mức độ xác minh dữ kiện'!I$3:I$12,"ĐL") -> 4 | D7: =COUNTIF('Mức độ xác minh dữ kiện'!I$3:I$12,"NB+ĐL")+COUNTIF('Mức độ xác minh dữ kiện'!I$3:I$12,"NB") -> 3 | E7: =COUNTIF('Mức độ xác minh dữ kiện'!I$3:I$12,"ĐT") -> 2 | F7: =COUNTIF('Mức độ xác minh dữ kiện'!I$3:I$12,"TT") -> 1 | G7: =COUNTIF('Mức độ xác minh dữ kiện'!I$3:I$12,"BC")+COUNTIF('Mức độ xác minh dữ kiện'!I$3:I$12,"LS") -> 1
A8: Cộng đồng & Con người | B8: =COUNTIF('Mức độ xác minh dữ kiện'!J$3:J$12,"NB+ĐL")+COUNTIF('Mức độ xác minh dữ kiện'!J$3:J$12,"NB")+COUNTIF('Mức độ xác minh dữ kiện'!J$3:J$12,"ĐL")+COUNTIF('Mức độ xác minh dữ kiện'!J$3:J$12,"ĐT") -> 9 | C8: =COUNTIF('Mức độ xác minh dữ kiện'!J$3:J$12,"NB+ĐL")+COUNTIF('Mức độ xác minh dữ kiện'!J$3:J$12,"ĐL") -> 7 | D8: =COUNTIF('Mức độ xác minh dữ kiện'!J$3:J$12,"NB+ĐL")+COUNTIF('Mức độ xác minh dữ kiện'!J$3:J$12,"NB") -> 1 | E8: =COUNTIF('Mức độ xác minh dữ kiện'!J$3:J$12,"ĐT") -> 2 | F8: =COUNTIF('Mức độ xác minh dữ kiện'!J$3:J$12,"TT") -> 1 | G8: =COUNTIF('Mức độ xác minh dữ kiện'!J$3:J$12,"BC")+COUNTIF('Mức độ xác minh dữ kiện'!J$3:J$12,"LS") -> 0
A9: Văn hóa & Di sản | B9: =COUNTIF('Mức độ xác minh dữ kiện'!K$3:K$12,"NB+ĐL")+COUNTIF('Mức độ xác minh dữ kiện'!K$3:K$12,"NB")+COUNTIF('Mức độ xác minh dữ kiện'!K$3:K$12,"ĐL")+COUNTIF('Mức độ xác minh dữ kiện'!K$3:K$12,"ĐT") -> 10 | C9: =COUNTIF('Mức độ xác minh dữ kiện'!K$3:K$12,"NB+ĐL")+COUNTIF('Mức độ xác minh dữ kiện'!K$3:K$12,"ĐL") -> 0 | D9: =COUNTIF('Mức độ xác minh dữ kiện'!K$3:K$12,"NB+ĐL")+COUNTIF('Mức độ xác minh dữ kiện'!K$3:K$12,"NB") -> 1 | E9: =COUNTIF('Mức độ xác minh dữ kiện'!K$3:K$12,"ĐT") -> 9 | F9: =COUNTIF('Mức độ xác minh dữ kiện'!K$3:K$12,"TT") -> 0 | G9: =COUNTIF('Mức độ xác minh dữ kiện'!K$3:K$12,"BC")+COUNTIF('Mức độ xác minh dữ kiện'!K$3:K$12,"LS") -> 0
A10: Gắn kết khách hàng | B10: =COUNTIF('Mức độ xác minh dữ kiện'!L$3:L$12,"NB+ĐL")+COUNTIF('Mức độ xác minh dữ kiện'!L$3:L$12,"NB")+COUNTIF('Mức độ xác minh dữ kiện'!L$3:L$12,"ĐL")+COUNTIF('Mức độ xác minh dữ kiện'!L$3:L$12,"ĐT") -> 9 | C10: =COUNTIF('Mức độ xác minh dữ kiện'!L$3:L$12,"NB+ĐL")+COUNTIF('Mức độ xác minh dữ kiện'!L$3:L$12,"ĐL") -> 0 | D10: =COUNTIF('Mức độ xác minh dữ kiện'!L$3:L$12,"NB+ĐL")+COUNTIF('Mức độ xác minh dữ kiện'!L$3:L$12,"NB") -> 2 | E10: =COUNTIF('Mức độ xác minh dữ kiện'!L$3:L$12,"ĐT") -> 7 | F10: =COUNTIF('Mức độ xác minh dữ kiện'!L$3:L$12,"TT") -> 1 | G10: =COUNTIF('Mức độ xác minh dữ kiện'!L$3:L$12,"BC")+COUNTIF('Mức độ xác minh dữ kiện'!L$3:L$12,"LS") -> 0

Sheet Resort coverage
A1: Tổng hợp minh chứng theo khu nghỉ dưỡng
A2: Khu nghỉ dưỡng | B2: Số khía cạnh có bằng chứng hiện tại | C2: Số khía cạnh có dữ liệu định lượng | D2: Số khía cạnh có nguồn bên ngoài | E2: Số khía cạnh chỉ có định tính | F2: Số khía cạnh thiếu minh chứng | G2: Số khía cạnh chỉ có bối cảnh/lịch sử | H2: Tình trạng quản lý / xác minh | I2: Kết luận
A3: Six Senses Ninh Van Bay | B3: =COUNTIF('Mức độ xác minh dữ kiện'!$E3:$L3,"NB+ĐL")+COUNTIF('Mức độ xác minh dữ kiện'!$E3:$L3,"NB")+COUNTIF('Mức độ xác minh dữ kiện'!$E3:$L3,"ĐL")+COUNTIF('Mức độ xác minh dữ kiện'!$E3:$L3,"ĐT") -> 8 | C3: =COUNTIF('Mức độ xác minh dữ kiện'!$E3:$L3,"NB+ĐL")+COUNTIF('Mức độ xác minh dữ kiện'!$E3:$L3,"ĐL") -> 5 | D3: =COUNTIF('Mức độ xác minh dữ kiện'!$E3:$L3,"NB+ĐL")+COUNTIF('Mức độ xác minh dữ kiện'!$E3:$L3,"NB") -> 3 | E3: =COUNTIF('Mức độ xác minh dữ kiện'!$E3:$L3,"ĐT") -> 2 | F3: =COUNTIF('Mức độ xác minh dữ kiện'!$E3:$L3,"TT") -> 0 | G3: =COUNTIF('Mức độ xác minh dữ kiện'!$E3:$L3,"BC")+COUNTIF('Mức độ xác minh dữ kiện'!$E3:$L3,"LS") -> 0 | H3: Có tên trong danh bạ GSTC; Control Union (GSTC-I), chu kỳ 2024–2027. Có thêm ghi nhận HICAP 2024. | I3: Độ phủ đủ 8 chiều; nổi bật về bằng chứng định lượng và nguồn đối chiếu bên ngoài ở đa dạng sinh học/cộng đồng.
A4: InterContinental Danang Sun Peninsula Resort | B4: =COUNTIF('Mức độ xác minh dữ kiện'!$E4:$L4,"NB+ĐL")+COUNTIF('Mức độ xác minh dữ kiện'!$E4:$L4,"NB")+COUNTIF('Mức độ xác minh dữ kiện'!$E4:$L4,"ĐL")+COUNTIF('Mức độ xác minh dữ kiện'!$E4:$L4,"ĐT") -> 8 | C4: =COUNTIF('Mức độ xác minh dữ kiện'!$E4:$L4,"NB+ĐL")+COUNTIF('Mức độ xác minh dữ kiện'!$E4:$L4,"ĐL") -> 1 | D4: =COUNTIF('Mức độ xác minh dữ kiện'!$E4:$L4,"NB+ĐL")+COUNTIF('Mức độ xác minh dữ kiện'!$E4:$L4,"NB") -> 2 | E4: =COUNTIF('Mức độ xác minh dữ kiện'!$E4:$L4,"ĐT") -> 5 | F4: =COUNTIF('Mức độ xác minh dữ kiện'!$E4:$L4,"TT") -> 0 | G4: =COUNTIF('Mức độ xác minh dữ kiện'!$E4:$L4,"BC")+COUNTIF('Mức độ xác minh dữ kiện'!$E4:$L4,"LS") -> 0 | H4: Green Globe xác nhận chứng nhận công khai; khu nghỉ dưỡng cũng công bố Kế hoạch Quản lý Bền vững 2026–2027. | I4: Độ phủ đủ 8 chiều; nhiều nội dung còn định tính, nhưng có xác minh bên ngoài về quản lý và một số nội dung khách/thiên nhiên.
A5: Banyan Tree Lang Co | B5: =COUNTIF('Mức độ xác minh dữ kiện'!$E5:$L5,"NB+ĐL")+COUNTIF('Mức độ xác minh dữ kiện'!$E5:$L5,"NB")+COUNTIF('Mức độ xác minh dữ kiện'!$E5:$L5,"ĐL")+COUNTIF('Mức độ xác minh dữ kiện'!$E5:$L5,"ĐT") -> 4 | C5: =COUNTIF('Mức độ xác minh dữ kiện'!$E5:$L5,"NB+ĐL")+COUNTIF('Mức độ xác minh dữ kiện'!$E5:$L5,"ĐL") -> 1 | D5: =COUNTIF('Mức độ xác minh dữ kiện'!$E5:$L5,"NB+ĐL")+COUNTIF('Mức độ xác minh dữ kiện'!$E5:$L5,"NB") -> 0 | E5: =COUNTIF('Mức độ xác minh dữ kiện'!$E5:$L5,"ĐT") -> 3 | F5: =COUNTIF('Mức độ xác minh dữ kiện'!$E5:$L5,"TT") -> 2 | G5: =COUNTIF('Mức độ xác minh dữ kiện'!$E5:$L5,"BC")+COUNTIF('Mức độ xác minh dữ kiện'!$E5:$L5,"LS") -> 2 | H5: Có tên trong danh bạ GSTC; Control Union (GSTC-I), chu kỳ 2025–2028. EarthCheck Gold 2022 chỉ dùng như bối cảnh lịch sử/cấp khu phức hợp. | I5: Bằng chứng công khai tập trung hơn vào quản lý, cộng đồng và trải nghiệm; chỉ số vận hành ở cấp cơ sở còn hạn chế.
A6: Topas Ecolodge | B6: =COUNTIF('Mức độ xác minh dữ kiện'!$E6:$L6,"NB+ĐL")+COUNTIF('Mức độ xác minh dữ kiện'!$E6:$L6,"NB")+COUNTIF('Mức độ xác minh dữ kiện'!$E6:$L6,"ĐL")+COUNTIF('Mức độ xác minh dữ kiện'!$E6:$L6,"ĐT") -> 7 | C6: =COUNTIF('Mức độ xác minh dữ kiện'!$E6:$L6,"NB+ĐL")+COUNTIF('Mức độ xác minh dữ kiện'!$E6:$L6,"ĐL") -> 2 | D6: =COUNTIF('Mức độ xác minh dữ kiện'!$E6:$L6,"NB+ĐL")+COUNTIF('Mức độ xác minh dữ kiện'!$E6:$L6,"NB") -> 0 | E6: =COUNTIF('Mức độ xác minh dữ kiện'!$E6:$L6,"ĐT") -> 5 | F6: =COUNTIF('Mức độ xác minh dữ kiện'!$E6:$L6,"TT") -> 1 | G6: =COUNTIF('Mức độ xác minh dữ kiện'!$E6:$L6,"BC")+COUNTIF('Mức độ xác minh dữ kiện'!$E6:$L6,"LS") -> 0 | H6: Được xác nhận nhận Giải Khách sạn Xanh ASEAN 2026; xem đây là ghi nhận độc lập, không phải kiểm toán chứng nhận toàn bộ chỉ số. | I6: Mạnh về cộng đồng, thu mua địa phương và bản sắc địa phương; ít bằng chứng hiện tại về đa dạng sinh học định lượng.
A7: The Westin Resort & Spa Cam Ranh | B7: =COUNTIF('Mức độ xác minh dữ kiện'!$E7:$L7,"NB+ĐL")+COUNTIF('Mức độ xác minh dữ kiện'!$E7:$L7,"NB")+COUNTIF('Mức độ xác minh dữ kiện'!$E7:$L7,"ĐL")+COUNTIF('Mức độ xác minh dữ kiện'!$E7:$L7,"ĐT") -> 8 | C7: =COUNTIF('Mức độ xác minh dữ kiện'!$E7:$L7,"NB+ĐL")+COUNTIF('Mức độ xác minh dữ kiện'!$E7:$L7,"ĐL") -> 4 | D7: =COUNTIF('Mức độ xác minh dữ kiện'!$E7:$L7,"NB+ĐL")+COUNTIF('Mức độ xác minh dữ kiện'!$E7:$L7,"NB") -> 0 | E7: =COUNTIF('Mức độ xác minh dữ kiện'!$E7:$L7,"ĐT") -> 4 | F7: =COUNTIF('Mức độ xác minh dữ kiện'!$E7:$L7,"TT") -> 0 | G7: =COUNTIF('Mức độ xác minh dữ kiện'!$E7:$L7,"BC")+COUNTIF('Mức độ xác minh dữ kiện'!$E7:$L7,"LS") -> 0 | H7: Marriott công bố trạng thái Travelife Certified; trong đợt rà soát công khai này chưa truy xuất được hồ sơ gốc từ danh bạ Travelife. | I7: Có độ phủ đủ 8 chiều và một số chỉ số vận hành đã chuẩn hóa; ít nguồn ngoài được truy xuất công khai trong đợt rà.
A8: Six Senses Con Dao | B8: =COUNTIF('Mức độ xác minh dữ kiện'!$E8:$L8,"NB+ĐL")+COUNTIF('Mức độ xác minh dữ kiện'!$E8:$L8,"NB")+COUNTIF('Mức độ xác minh dữ kiện'!$E8:$L8,"ĐL")+COUNTIF('Mức độ xác minh dữ kiện'!$E8:$L8,"ĐT") -> 8 | C8: =COUNTIF('Mức độ xác minh dữ kiện'!$E8:$L8,"NB+ĐL")+COUNTIF('Mức độ xác minh dữ kiện'!$E8:$L8,"ĐL") -> 4 | D8: =COUNTIF('Mức độ xác minh dữ kiện'!$E8:$L8,"NB+ĐL")+COUNTIF('Mức độ xác minh dữ kiện'!$E8:$L8,"NB") -> 0 | E8: =COUNTIF('Mức độ xác minh dữ kiện'!$E8:$L8,"ĐT") -> 4 | F8: =COUNTIF('Mức độ xác minh dữ kiện'!$E8:$L8,"TT") -> 0 | G8: =COUNTIF('Mức độ xác minh dữ kiện'!$E8:$L8,"BC")+COUNTIF('Mức độ xác minh dữ kiện'!$E8:$L8,"LS") -> 0 | H8: Có tên trong danh bạ GSTC; Control Union (GSTC-I), chu kỳ 2024–2027, mã GSTC HACU240332-1. | I8: Độ phủ đủ 8 chiều, nhiều chỉ số định lượng ở cấp cơ sở; có xác minh quản lý qua GSTC.
A9: Mango Bay Phu Quoc | B9: =COUNTIF('Mức độ xác minh dữ kiện'!$E9:$L9,"NB+ĐL")+COUNTIF('Mức độ xác minh dữ kiện'!$E9:$L9,"NB")+COUNTIF('Mức độ xác minh dữ kiện'!$E9:$L9,"ĐL")+COUNTIF('Mức độ xác minh dữ kiện'!$E9:$L9,"ĐT") -> 6 | C9: =COUNTIF('Mức độ xác minh dữ kiện'!$E9:$L9,"NB+ĐL")+COUNTIF('Mức độ xác minh dữ kiện'!$E9:$L9,"ĐL") -> 2 | D9: =COUNTIF('Mức độ xác minh dữ kiện'!$E9:$L9,"NB+ĐL")+COUNTIF('Mức độ xác minh dữ kiện'!$E9:$L9,"NB") -> 0 | E9: =COUNTIF('Mức độ xác minh dữ kiện'!$E9:$L9,"ĐT") -> 4 | F9: =COUNTIF('Mức độ xác minh dữ kiện'!$E9:$L9,"TT") -> 1 | G9: =COUNTIF('Mức độ xác minh dữ kiện'!$E9:$L9,"BC")+COUNTIF('Mức độ xác minh dữ kiện'!$E9:$L9,"LS") -> 1 | H9: Chưa tìm thấy chứng nhận phát triển bền vững bên thứ ba còn hiệu lực trong các nguồn công khai đã rà. | I9: Nổi bật ở thu mua địa phương và cộng đồng; một phần bằng chứng đa dạng sinh học là dữ liệu lịch sử.
A10: Avana Retreat | B10: =COUNTIF('Mức độ xác minh dữ kiện'!$E10:$L10,"NB+ĐL")+COUNTIF('Mức độ xác minh dữ kiện'!$E10:$L10,"NB")+COUNTIF('Mức độ xác minh dữ kiện'!$E10:$L10,"ĐL")+COUNTIF('Mức độ xác minh dữ kiện'!$E10:$L10,"ĐT") -> 6 | C10: =COUNTIF('Mức độ xác minh dữ kiện'!$E10:$L10,"NB+ĐL")+COUNTIF('Mức độ xác minh dữ kiện'!$E10:$L10,"ĐL") -> 1 | D10: =COUNTIF('Mức độ xác minh dữ kiện'!$E10:$L10,"NB+ĐL")+COUNTIF('Mức độ xác minh dữ kiện'!$E10:$L10,"NB") -> 1 | E10: =COUNTIF('Mức độ xác minh dữ kiện'!$E10:$L10,"ĐT") -> 4 | F10: =COUNTIF('Mức độ xác minh dữ kiện'!$E10:$L10,"TT") -> 2 | G10: =COUNTIF('Mức độ xác minh dữ kiện'!$E10:$L10,"BC")+COUNTIF('Mức độ xác minh dữ kiện'!$E10:$L10,"LS") -> 0 | H10: Có đánh giá đa dạng sinh học/văn hóa sinh học từ Guardians of Earth; đây là đánh giá bên ngoài, không phải chứng nhận phát triển bền vững của khách sạn. | I10: Nổi bật ở cộng đồng và đa dạng sinh học; còn khoảng trống công khai ở năng lượng và nước.
A11: Silk Sense Hoi An River Resort | B11: =COUNTIF('Mức độ xác minh dữ kiện'!$E11:$L11,"NB+ĐL")+COUNTIF('Mức độ xác minh dữ kiện'!$E11:$L11,"NB")+COUNTIF('Mức độ xác minh dữ kiện'!$E11:$L11,"ĐL")+COUNTIF('Mức độ xác minh dữ kiện'!$E11:$L11,"ĐT") -> 8 | C11: =COUNTIF('Mức độ xác minh dữ kiện'!$E11:$L11,"NB+ĐL")+COUNTIF('Mức độ xác minh dữ kiện'!$E11:$L11,"ĐL") -> 5 | D11: =COUNTIF('Mức độ xác minh dữ kiện'!$E11:$L11,"NB+ĐL")+COUNTIF('Mức độ xác minh dữ kiện'!$E11:$L11,"NB") -> 0 | E11: =COUNTIF('Mức độ xác minh dữ kiện'!$E11:$L11,"ĐT") -> 3 | F11: =COUNTIF('Mức độ xác minh dữ kiện'!$E11:$L11,"TT") -> 0 | G11: =COUNTIF('Mức độ xác minh dữ kiện'!$E11:$L11,"BC")+COUNTIF('Mức độ xác minh dữ kiện'!$E11:$L11,"LS") -> 0 | H11: Khu nghỉ dưỡng công bố Travelife Gold và có Báo cáo Phát triển Bền vững chi tiết; chưa truy xuất được hồ sơ gốc từ danh bạ Travelife trong đợt rà này. | I11: Độ phủ đủ 8 chiều và nhiều chỉ số vận hành định lượng/chuẩn hóa; nguồn ngoài còn hạn chế trong đợt rà công khai.
A12: Legacy Mekong | B12: =COUNTIF('Mức độ xác minh dữ kiện'!$E12:$L12,"NB+ĐL")+COUNTIF('Mức độ xác minh dữ kiện'!$E12:$L12,"NB")+COUNTIF('Mức độ xác minh dữ kiện'!$E12:$L12,"ĐL")+COUNTIF('Mức độ xác minh dữ kiện'!$E12:$L12,"ĐT") -> 4 | C12: =COUNTIF('Mức độ xác minh dữ kiện'!$E12:$L12,"NB+ĐL")+COUNTIF('Mức độ xác minh dữ kiện'!$E12:$L12,"ĐL") -> 0 | D12: =COUNTIF('Mức độ xác minh dữ kiện'!$E12:$L12,"NB+ĐL")+COUNTIF('Mức độ xác minh dữ kiện'!$E12:$L12,"NB") -> 2 | E12: =COUNTIF('Mức độ xác minh dữ kiện'!$E12:$L12,"ĐT") -> 2 | F12: =COUNTIF('Mức độ xác minh dữ kiện'!$E12:$L12,"TT") -> 3 | G12: =COUNTIF('Mức độ xác minh dữ kiện'!$E12:$L12,"BC")+COUNTIF('Mức độ xác minh dữ kiện'!$E12:$L12,"LS") -> 1 | H12: Từ cuối 2025, khu nghỉ dưỡng thuộc Autograph Collection của Marriott và nằm trong khung phát triển bền vững cấp tập đoàn | I12: Đã có evidence về vài khía cạnh, nhưng dữ liệu định lượng và KPI môi trường, xã hội từ khu nghỉ dưỡng vẫn còn hạn chế

Sheet Kết luận
A1: Tổng hợp minh chứng theo khu nghỉ dưỡng
A2: Kết quả chính | B2: Minh chứng từ bộ dữ liệu | C2: Ý nghĩa phân tích | D2: Cần tránh kết luận
A3: 1. Phạm vi công bố rộng nhưng mức độ minh chứng giữa các khía cạnh rất khác nhau. | B3: Văn hóa & Di sản: 10/10 khu nghỉ dưỡng có thông tin nhưng 0/10 có dữ liệu định lượng. Cộng đồng & Con người: 9/10 có thông tin hiện tại, trong đó 7/10 có dữ liệu định lượng. | C3: Việc một nội dung được đề cập nhiều không có nghĩa nội dung đó đã được đo lường đầy đủ. | D3: Không kết luận Văn hóa & Di sản kém quan trọng chỉ vì thiếu KPI.
A4: 2. Phát triển bền vững trong mẫu không chỉ xoay quanh môi trường; Cộng đồng & Con người là một trong những khía cạnh được đo lường rõ nhất. | B4: Cộng đồng & Con người: 9/10 có bằng chứng hiện tại, 7/10 có dữ liệu định lượng — cao hơn Năng lượng (3/10) và Nước (2/10). | C4: Có thể xem phát triển bền vững trong hospitality qua việc làm, đào tạo, thu mua địa phương và sinh kế, không chỉ qua điện, nước hay nhựa. | D4: Không suy ra tác động xã hội thực tế tốt hơn tác động môi trường chỉ vì có nhiều số liệu hơn.
A5: 3. Hiệu suất môi trường vẫn khó so sánh trực tiếp giữa các khu nghỉ dưỡng. | B5: Năng lượng và Nước đều có bằng chứng hiện tại ở 7/10 khu nghỉ dưỡng; dữ liệu định lượng lần lượt là 3/10 và 2/10. Westin Cam Ranh và Silk Sense có chỉ số cường độ rõ theo đêm phòng/đêm khách. | C5: Dữ liệu công khai chưa đủ đồng nhất để so sánh hiệu quả sử dụng tài nguyên giữa các cơ sở. | D5: Không so sánh trực tiếp kWh, nước hay carbon nếu mẫu số và phạm vi đo khác nhau.
A6: 4. Thông tin công bố vẫn thiên về thực hành và đầu ra hơn là thay đổi thực tế. | B6: Trong 108 mục cốt lõi + bổ trợ: 53 mục ở mức Thực hành, 44 mục ở mức Đầu ra, khoảng 10 mục cho thấy thay đổi và 1 mục là Cam kết. | C6: Các khu nghỉ dưỡng khá rõ về việc đã làm gì và tạo ra bao nhiêu, nhưng ít thông tin hơn về thay đổi dài hạn. | D6: Không coi đầu ra là tác động cuối cùng.
A7: 5. Gắn kết khách hàng khá phổ biến nhưng ít được đo lường ở mức kết quả. | B7: Gắn kết khách hàng có bằng chứng hiện tại ở 9/10 khu nghỉ dưỡng; ma trận chưa có khu nghỉ dưỡng nào đạt nhóm định lượng ở cấp so sánh cho khía cạnh này. | C7: Phát triển bền vững đã đi vào trải nghiệm khách ở nhiều nơi, nhưng công bố chủ yếu cho biết hoạt động tồn tại hoặc số lượt tham gia, ít đo thay đổi nhận thức/hành vi. | D7: Không kết luận khách đã thay đổi hành vi nếu chưa có minh chứng.
A8: 6. Xác minh bên ngoài tập trung nhiều hơn ở chứng nhận/quản lý và một số dự án đa dạng sinh học. | B8: GSTC/Green Globe xác minh ở cấp hệ thống quản lý; đa dạng sinh học có thêm GreenViet, Guardians of Earth… Trong khi nhiều KPI về năng lượng, chất thải và thu mua vẫn do doanh nghiệp tự công bố. | C8: Chứng nhận hệ thống và xác minh từng KPI là hai việc khác nhau. | D8: Không dùng chứng nhận để nói mọi KPI của khu nghỉ dưỡng đều đã được kiểm toán.
A9: 7. Phạm vi công bố và mức độ mạnh của minh chứng là hai khái niệm khác nhau. | B9: InterContinental có thông tin ở 8/8 khía cạnh nhưng chỉ 1 khía cạnh có dữ liệu định lượng; Silk Sense cũng 8/8 nhưng có 5 khía cạnh định lượng. Banyan Tree có chứng nhận mạnh nhưng KPI vận hành ở cấp khu nghỉ dưỡng còn ít. | C9: Không thể đánh giá mức độ minh bạch chỉ bằng số khía cạnh hoặc số mục thông tin. | D9: Không chuyển kết quả thành bảng xếp hạng khu nghỉ dưỡng nào 'bền vững hơn'.

Sheet Dữ liệu thô
A1: Resort | B1: Năm | C1: Dimension | D1: Practice / Initiative | E1: Thông tin / Minh chứng chính | F1: Keep? | G1: Chỉ số | H1: Đơn vị | I1: Loại minh chứng | J1: Guest-facing? | K1: Evidence Stage | L1: Ghi chú | M1: Discussion Tag | N1: Operational Area(s) | O1: Mức độ tích hợp | P1: Nguồn | Q1: Source Link
A2: Six Senses Ninh Van Bay | B2: 2025 | C2: Energy & Climate | D2: Solar energy – Ninh Van Greens | E2: Solar farm tạo khoảng 26–28% điện sử dụng của resort; năm 2025 tạo 739.782 kWh điện tái tạo. | F2: Core | G2: 739782 | H2: kWh | I2: B – Doanh nghiệp công bố định lượng | J2: No – Back-of-house | K2: Output | L2: KPI định lượng rõ, nhưng là số liệu doanh nghiệp tự công bố; chưa cho biết cường độ sử dụng năng lượng hay mức giảm so với mốc cơ sở. | M2: Integration; Evidence & Transparency | N2: Engineering / Sustainability | O2: Tích hợp vào vận hành | P2: Trang chính thức của khu nghỉ dưỡng | Q2: https://www.sixsenses.com/en/hotels-resorts/asia-the-pacific/vietnam/ninh-van-bay/sustainability/
A3: Six Senses Ninh Van Bay | B3: Current review | C3: Energy & Climate | D3: Energy intensity trend | E3: Trong các nguồn đã rà, chưa tìm thấy KPI công khai kiểu kWh/occupied room hoặc kWh/guest night của riêng Ninh Van Bay theo thời gian. | F3: Data gap | I3: E – Chưa tìm thấy minh chứng cụ thể | J3: No – Back-of-house | K3: Data gap | L3: 739.782 kWh là đầu ra của điện mặt trời, không cho biết tổng hiệu quả năng lượng của khu nghỉ dưỡng có cải thiện hay không. | M3: Evidence & Transparency | N3: Engineering / Sustainability | O3: Tích hợp vào vận hành | Q3: https://www.sixsenses.com/en/hotels-resorts/asia-the-pacific/vietnam/ninh-van-bay/sustainability/
A4: Six Senses Ninh Van Bay | B4: Current review | C4: Energy & Climate | D4: Property-level GHG emissions | E4: Có brand-level climate measurement approach, nhưng chưa thấy Scope 1/2 emissions hoặc carbon/occupied room riêng của Ninh Van Bay trong các nguồn đã rà. | F4: Data gap | I4: E – Chưa tìm thấy minh chứng cụ thể | J4: No – Back-of-house | K4: Data gap | L4: Giúp phân biệt quản trị cấp thương hiệu với hiệu suất công bố cấp khu nghỉ dưỡng. | M4: Evidence & Transparency | N4: Management / Engineering / Sustainability | O4: Tích hợp ở hệ thống quản lý | Q4: https://www.sixsenses.com/en/sustainability/impacts/
A5: Six Senses Ninh Van Bay | B5: Current | C5: Water | D5: Water conservation in resort operations | E5: Property mô tả water conservation là một phần của định hướng vận hành bền vững tại resort. | F5: Supporting | I5: C – Doanh nghiệp công bố định tính | J5: No – Back-of-house | K5: Practice | L5: Có mô tả thực hành nhưng chưa có KPI định lượng về lượng nước sử dụng hoặc tiết kiệm. | M5: Breadth; Evidence & Transparency | N5: Engineering / Sustainability | O5: Tích hợp vào vận hành | P5: Trang chính thức của khu nghỉ dưỡng | Q5: https://www.sixsenses.com/en/hotels-resorts/asia-the-pacific/vietnam/ninh-van-bay/sustainability/
A6: Six Senses Ninh Van Bay | B6: Current review | C6: Water | D6: Water-use performance | E6: Chưa tìm thấy water/guest night, water/occupied room hoặc reduction % công khai cho riêng property trong các nguồn đã rà. | F6: Data gap | I6: E – Chưa tìm thấy minh chứng cụ thể | J6: No – Back-of-house | K6: Data gap | L6: Nên giữ để đối chiếu với các khu nghỉ dưỡng có KPI hiệu suất sử dụng nước nếu xuất hiện trong mẫu nghiên cứu. | M6: Evidence & Transparency | N6: Engineering / Sustainability | O6: Tích hợp vào vận hành | Q6: https://www.sixsenses.com/en/hotels-resorts/asia-the-pacific/vietnam/ninh-van-bay/sustainability/
A7: Six Senses Ninh Van Bay | B7: 2025 | C7: Waste & Plastic | D7: Reusable glass bottles | E7: 156.288 chai nhựa dùng một lần được thay thế bằng chai thủy tinh tái sử dụng. | F7: Core | G7: 156288 | H7: bottles | I7: B – Doanh nghiệp công bố định lượng | J7: Yes – Visible | K7: Output | L7: Đầu ra dễ hiểu và có thể so sánh nếu khu nghỉ dưỡng khác cũng công bố chai nhựa tránh dùng; chưa phải chất thải kết quả tổng thể. | M7: Evidence & Transparency; Integration | N7: F&B / Rooms / Sustainability | O7: Tích hợp liên phòng ban | P7: Trang chính thức của khu nghỉ dưỡng | Q7: https://www.sixsenses.com/en/hotels-resorts/asia-the-pacific/vietnam/ninh-van-bay/sustainability/
A8: Six Senses Ninh Van Bay | B8: 2025 | C8: Waste & Plastic | D8: Community Waste Care | E8: Trash to Treasure, Master Chef Upcycling, beach clean-ups và conservation activities thu hút 232 residents/hosts/guests và thu gom 1.961 kg rác. | F8: Supporting | G8: 1961 | H8: kg waste | I8: B – Doanh nghiệp công bố định lượng | J8: Yes – Participatory | K8: Output | L8: Vừa là hoạt động về chất thải vừa có cộng đồng/sự tham gia của khách; khía cạnh chính là Chất thải & Nhựa để tránh tính trùng. | M8: Community; Guest Experience; Integration | N8: Sustainability / Community / Experience | O8: Tích hợp với cộng đồng | P8: Trang chính thức của khu nghỉ dưỡng | Q8: https://www.sixsenses.com/en/hotels-resorts/asia-the-pacific/vietnam/ninh-van-bay/sustainability/
A9: Six Senses Ninh Van Bay | B9: 2025 | C9: Waste & Plastic | D9: Composting | E9: 4.200 kg phân hữu cơ/compost được sản xuất từ nguồn hữu cơ tại property trong năm 2025. | F9: Supporting | G9: 4200 | H9: kg | I9: B – Doanh nghiệp công bố định lượng | J9: No – Back-of-house | K9: Output | L9: Cho thấy tuần hoàn trong vận hành, nhưng chưa biết tỷ lệ rác hữu cơ được phân hữu cơ trên tổng chất thải. | M9: Integration; Evidence & Transparency | N9: F&B / Gardens / Sustainability | O9: Tích hợp vào vận hành | P9: Trang chính thức của khu nghỉ dưỡng | Q9: https://www.sixsenses.com/en/hotels-resorts/asia-the-pacific/vietnam/ninh-van-bay/sustainability/
A10: Six Senses Ninh Van Bay | B10: Current review | C10: Waste & Plastic | D10: Overall waste performance | E10: Có compost, bottles avoided và community waste outputs nhưng chưa thấy total waste generated, diversion rate hoặc waste/guest night. | F10: Data gap | I10: E – Chưa tìm thấy minh chứng cụ thể | J10: No – Back-of-house | K10: Data gap | L10: Quan trọng cho phần Thảo luận: nhiều đầu ra riêng lẻ không đồng nghĩa đã có chỉ số kết quả/hiệu suất tổng thể. | M10: Evidence & Transparency | N10: Engineering / Sustainability / F&B | O10: Tích hợp vào vận hành | Q10: https://www.sixsenses.com/en/hotels-resorts/asia-the-pacific/vietnam/ninh-van-bay/sustainability/
A11: Six Senses Ninh Van Bay | B11: 2025 | C11: Food & Procurement | D11: Organic gardens / Solar Fresh-Cuts | E11: Ba khu vườn sản xuất 13.849 kg rau quả hữu cơ; Solar Fresh-Cuts trồng herbs, fruits và vegetables dùng cho nhà hàng. | F11: Core | G11: 13849 | H11: kg | I11: B – Doanh nghiệp công bố định lượng | J11: Yes – Visible / experience-linked | K11: Output | L11: Một thực hành liên kết thu mua và F&B; phù hợp để phân tích tích hợp vào vận hành. | M11: Integration; Guest Experience | N11: F&B / Procurement / Sustainability | O11: Tích hợp liên phòng ban | P11: Trang chính thức của khu nghỉ dưỡng | Q11: https://www.sixsenses.com/en/hotels-resorts/asia-the-pacific/vietnam/ninh-van-bay/sustainability/
A12: Six Senses Ninh Van Bay | B12: Current | C12: Food & Procurement | D12: Responsible sourcing | E12: Property mô tả việc ưu tiên các nguồn nguyên liệu được khai thác/cung ứng có trách nhiệm trong hoạt động vận hành. | F12: Supporting | I12: C – Doanh nghiệp công bố định tính | J12: No – Back-of-house | K12: Practice | L12: Mô tả có ý nghĩa nhưng chưa có tỷ lệ địa phương/thu mua có trách nhiệm cụ thể. | M12: Evidence & Transparency | N12: Procurement / F&B / Sustainability | O12: Tích hợp vào vận hành | P12: Trang chính thức của khu nghỉ dưỡng | Q12: https://www.sixsenses.com/en/hotels-resorts/asia-the-pacific/vietnam/ninh-van-bay/sustainability/
A13: Six Senses Ninh Van Bay | B13: Current review | C13: Food & Procurement | D13: Local / responsible sourcing share | E13: Chưa tìm thấy % spending hoặc % food sourced locally/responsibly cho riêng Ninh Van Bay trong các nguồn đã rà. | F13: Data gap | I13: E – Chưa tìm thấy minh chứng cụ thể | J13: No – Back-of-house | K13: Data gap | L13: Giúp phân biệt thu mua commitment với mức độ thu mua được đo lường. | M13: Evidence & Transparency | N13: Procurement / F&B / Sustainability | O13: Tích hợp vào vận hành | Q13: https://www.sixsenses.com/en/hotels-resorts/asia-the-pacific/vietnam/ninh-van-bay/sustainability/
A14: Six Senses Ninh Van Bay | B14: 2019–2025 | C14: Biodiversity & Ecosystems | D14: Black-shanked douc langur population | E14: Property công bố số cá thể được ghi nhận tại Hòn Hèo tăng từ 109 năm 2019 lên 211 năm 2025. | F14: Core | G14: 211 | H14: individuals | I14: B – Doanh nghiệp công bố định lượng | J14: Yes – Experience-integrated | K14: Outcome indicator | L14: Gần kết quả hơn hoạt động/đầu ra, nhưng không được suy ra toàn bộ mức tăng là causal effect của khu nghỉ dưỡng. | M14: Evidence & Transparency; Interesting Case | N14: Sustainability / Biodiversity / Experience | O14: Tích hợp với khách / điểm đến | P14: Trang chính thức của khu nghỉ dưỡng | Q14: https://www.sixsenses.com/en/hotels-resorts/asia-the-pacific/vietnam/ninh-van-bay/sustainability/
A15: Six Senses Ninh Van Bay | B15: 2025 | C15: Biodiversity & Ecosystems | D15: Coral restoration | E15: Duy trì 80 coral frames, lắp 12 khung mới, cấy lại 200 coral fragments, hơn 250 giờ monitoring/maintenance; 128 guests tham gia. | F15: Core | G15: 200 | H15: coral fragments | I15: B – Doanh nghiệp công bố định lượng | J15: Yes – Participatory | K15: Output | L15: Rất giàu đầu ra chỉ sốs và có sự tham gia của khách; cần phân biệt phục hồi đầu ra với kết quả sinh thái. | M15: Guest Experience; Integration; Evidence & Transparency | N15: Marine / Sustainability / Experience | O15: Tích hợp với khách / điểm đến | P15: Trang chính thức của khu nghỉ dưỡng | Q15: https://www.sixsenses.com/en/hotels-resorts/asia-the-pacific/vietnam/ninh-van-bay/sustainability/
A16: Six Senses Ninh Van Bay | B16: 2019–2025 | C16: Biodiversity & Ecosystems | D16: Langur monitoring – partner corroboration | E16: GreenViet cũng báo cáo giám sát dài hạn cho thấy quần thể từ 109 cá thể năm 2019 lên 211 cá thể năm 2025. | F16: Core | G16: 211 | H16: individuals | I16: D – Xác nhận từ đối tác bên ngoài | J16: Yes – Experience-integrated | K16: Outcome indicator | L16: Nguồn đối tác corrobotỷ lệs xu hướng đối tượng; GreenViet là đối tác bảo tồn nên không gọi là independent audit. | M16: Evidence & Transparency | N16: Sustainability / Biodiversity / Research | O16: Tích hợp nghiên cứu / bảo tồn | P16: GreenViet | Q16: https://greenviet.org/tin-tuc/6-nam-dong-hanh-bao-ton-cha-va-chan-den-dau-an-hop-tac-greenviet-six-senses-ninh-van-bay/
A17: Six Senses Ninh Van Bay | B17: 2019–2024 | C17: Biodiversity & Ecosystems | D17: Five-year biodiversity survey | E17: GreenViet báo cáo hơn 300 loài động, thực vật được ghi nhận; 7 loài động vật và 10 loài thực vật thuộc các danh sách quý hiếm. | F17: Supporting | G17: 300 | H17: > species | I17: D – Xác nhận từ đối tác bên ngoài | J17: No – Research-facing | K17: Output | L17: Nguồn đối tác giúp đối chiếu quy mô nghiên cứu đa dạng sinh học; phạm vi khác với con số 150 loài do khu nghỉ dưỡng công bố từ năm 2022. | M17: Evidence & Transparency | N17: Biodiversity / Sustainability / Research | O17: Tích hợp nghiên cứu / bảo tồn | P17: GreenViet | Q17: https://greenviet.org/tin-tuc/thanh-tuu-xanh-tu-5-nam-hop-tac-giua-greenviet-va-six-senses-ninh-van-ba/
A18: Six Senses Ninh Van Bay | B18: 2022–2025 | C18: Biodiversity & Ecosystems | D18: Forest biodiversity research | E18: Six Senses công bố đã nhận diện 150 species trong surrounding forest từ 2022, gồm 10 rare plant species; Curcuma sixsensesensis được công nhận năm 2022. | F18: Supporting | G18: 150 | H18: species | I18: B – Doanh nghiệp công bố định lượng | J18: No – Research-facing | K18: Output | L18: Không gộp trực tiếp với số 300+ loài của GreenViet vì phạm vi/thời kỳ khác. | M18: Evidence & Transparency | N18: Biodiversity / Sustainability / Research | O18: Tích hợp nghiên cứu / bảo tồn | P18: Trang chính thức của khu nghỉ dưỡng | Q18: https://www.sixsenses.com/en/hotels-resorts/asia-the-pacific/vietnam/ninh-van-bay/sustainability/
A19: Six Senses Ninh Van Bay | B19: 2025 | C19: Biodiversity & Ecosystems | D19: Mangrove restoration | E19: Six Senses công bố hơn 150 hosts tham gia trồng 14.700 cây ngập mặn tại Đầm Bấy và Đầm Thị Nại. | F19: Supporting | G19: 14700 | H19: trees | I19: B – Doanh nghiệp công bố định lượng | J19: No – Staff/community-facing | K19: Output | L19: Đầu ra phục hồi hệ sinh thái; chưa phải kết quả như survival tỷ lệ hoặc đa dạng sinh học change. | M19: Integration; Community | N19: Sustainability / HR / Community | O19: Tích hợp liên phòng ban | P19: Trang chính thức của khu nghỉ dưỡng | Q19: https://www.sixsenses.com/en/hotels-resorts/asia-the-pacific/vietnam/ninh-van-bay/sustainability/
A20: Six Senses Ninh Van Bay | B20: 2025 | C20: Biodiversity & Ecosystems | D20: Natural coral spawning | E20: Ngày 18/4/2025, resort lần đầu ghi nhận hiện tượng sinh sản tự nhiên của san hô trong restoration area. | F20: Supporting | G20: 1 | H20: recorded event | I20: B – Doanh nghiệp công bố định lượng | J20: No – Research-facing | K20: Outcome indicator | L20: Đây là chỉ báo thay đổi sinh thái đáng chú ý, nhưng một lần quan sát chưa đủ để chứng minh tác động dài hạn. | M20: Interesting Case; Evidence & Transparency | N20: Marine Biology / Sustainability | O20: Tích hợp nghiên cứu / bảo tồn | P20: Trang chính thức của khu nghỉ dưỡng | Q20: https://www.sixsenses.com/en/hotels-resorts/asia-the-pacific/vietnam/ninh-van-bay/sustainability/
A21: Six Senses Ninh Van Bay | B21: 2019–2025 | C21: Biodiversity & Ecosystems | D21: Camera-trap wildlife monitoring | E21: GreenViet ghi nhận các loài quý hiếm qua camera trap như Cheo cheo lưng bạc, Tê tê Java, Cu li nhỏ/Mèo rừng; giai đoạn 2023–2025 tiếp tục có wildlife records. | F21: Appendix | I21: D – Xác nhận từ đối tác bên ngoài | J21: No – Research-facing | K21: Output | L21: Cho thấy hoạt động theo dõi khoa học kéo dài, nhưng chưa có một KPI tổng hợp duy nhất để so sánh. | M21: Interesting Case; Evidence & Transparency | N21: Biodiversity / Research | O21: Tích hợp nghiên cứu / bảo tồn | P21: GreenViet | Q21: https://greenviet.org/tin-tuc/thanh-tuu-xanh-tu-5-nam-hop-tac-giua-greenviet-va-six-senses-ninh-van-ba/
A22: Six Senses Ninh Van Bay | B22: 2025 | C22: Community & People | D22: Education empowerment | E22: Hơn 1.000 students hưởng lợi từ educational programs; 138 university students tham gia sustainability workshops; 400 books được tặng. | F22: Core | G22: 1000 | H22: > students | I22: B – Doanh nghiệp công bố định lượng | J22: No – Community-facing | K22: Output | L22: Có đầu ra xã hội rõ nhưng chưa có longitudinal kết quả về việc làm/income/nghề nghiệp progression. | M22: Community; Evidence & Transparency | N22: HR / Education / Community / Sustainability | O22: Tích hợp với cộng đồng | P22: Trang chính thức của khu nghỉ dưỡng | Q22: https://www.sixsenses.com/en/hotels-resorts/asia-the-pacific/vietnam/ninh-van-bay/sustainability/
A23: Six Senses Ninh Van Bay | B23: H1 2025 | C23: Community & People | D23: Staff conservation training | E23: GreenViet ghi nhận 6 hoạt động nội bộ về biodiversity/conservation, thu hút tổng cộng 62 nhân viên tham gia. | F23: Core | G23: 62 | H23: staff | I23: D – Xác nhận từ đối tác bên ngoài | J23: No – Staff-facing | K23: Output | L23: Minh chứng tốt cho góc nhìn quản lý/tích hợp: nhân viên được trang bị kiến thức để truyền tải tới khách. | M23: Integration; Community | N23: HR / Sustainability / Experience | O23: Tích hợp liên phòng ban | P23: GreenViet | Q23: https://greenviet.org/tin-tuc/truyen-cam-hung-yeu-va-bao-ve-thien-nhien-tai-six-senses-ninh-van-bay/
A24: Six Senses Ninh Van Bay | B24: 2025 | C24: Community & People | D24: Water for All | E24: Lắp hệ thống RO–UV tại Ninh Ich Primary School, cung cấp nước uống an toàn cho 200 students & teachers; awareness sessions cho hơn 180 người. | F24: Core | G24: 200 | H24: students & teachers | I24: B – Doanh nghiệp công bố định lượng | J24: No – Community-facing | K24: Output | L24: khía cạnh chính là cộng đồng & People vì đây là cộng đồng access project, không phải KPI sử dụng nước trong khu nghỉ dưỡng. | M24: Community; Evidence & Transparency | N24: Community / Sustainability / Water | O24: Tích hợp với cộng đồng | P24: Trang chính thức của khu nghỉ dưỡng | Q24: https://www.sixsenses.com/en/hotels-resorts/asia-the-pacific/vietnam/ninh-van-bay/sustainability/
A25: Six Senses Ninh Van Bay | B25: 2025 | C25: Community & People | D25: Conservation awareness for local community & students | E25: Six Senses công bố 457 người dân địa phương và học sinh/sinh viên tham gia reforestation, school visits, university presentations, wildlife education và Earth Day exhibitions. | F25: Supporting | G25: 457 | H25: people | I25: B – Doanh nghiệp công bố định lượng | J25: No – Community-facing | K25: Output | L25: Không gộp với con số 457 sự tham gia của kháchs do GreenViet công bố; hai nguồn mô tả khác đối tượng. | M25: Community; Evidence & Transparency | N25: Sustainability / Community / Education | O25: Tích hợp với cộng đồng | P25: Trang chính thức của khu nghỉ dưỡng | Q25: https://www.sixsenses.com/en/hotels-resorts/asia-the-pacific/vietnam/ninh-van-bay/sustainability/
A26: Six Senses Ninh Van Bay | B26: 2024–2025 | C26: Community & People | D26: Solar for Life | E26: Năm 2025 lắp 18 hệ thống đèn năng lượng mặt trời; Six Senses cho biết dự án mang lợi ích cho hơn 1.330 người trong 2024–2025. | F26: Supporting | G26: 1330 | H26: > people benefited | I26: B – Doanh nghiệp công bố định lượng | J26: No – Community-facing | K26: Output | L26: Dùng cộng đồng & People làm khía cạnh chính vì chỉ số chính là người hưởng lợi reach, dù giải pháp dùng điện mặt trời. | M26: Community; Integration | N26: Community / Sustainability | O26: Tích hợp với cộng đồng | P26: Trang chính thức của khu nghỉ dưỡng | Q26: https://www.sixsenses.com/vn/hotels-resorts/asia-the-pacific/vietnam/ninh-van-bay/sustainability/
A27: Six Senses Ninh Van Bay | B27: H1 2025 | C27: Community & People | D27: Student environmental field trip | E27: GreenViet ghi nhận 2 chương trình giáo dục cho học sinh; tiêu biểu có 26 học sinh và giáo viên của Happy Village School tham gia field trip. | F27: Supporting | G27: 26 | H27: students & teachers | I27: D – Xác nhận từ đối tác bên ngoài | J27: Yes – Participatory | K27: Output | L27: đối tác corroboration cho social/cộng đồng dimension. | M27: Community | N27: Sustainability / Education / Community | O27: Tích hợp với cộng đồng | P27: GreenViet | Q27: https://greenviet.org/tin-tuc/truyen-cam-hung-yeu-va-bao-ve-thien-nhien-tai-six-senses-ninh-van-bay/
A28: Six Senses Ninh Van Bay | B28: Current review | C28: Community & People | D28: Local workforce / employment outcome | E28: Property nói có scholarships, internships và employment opportunities nhưng chưa thấy % local workforce, retention hoặc career outcome dài hạn. | F28: Data gap | I28: E – Chưa tìm thấy minh chứng cụ thể | J28: No – Back-of-house | K28: Data gap | L28: Giúp kiểm tra social phát triển bền vững có đi từ programme đầu ra tới việc làm kết quả hay chưa. | M28: Community; Evidence & Transparency | N28: HR / Community / Sustainability | O28: Tích hợp ở hệ thống quản lý | Q28: https://www.sixsenses.com/en/hotels-resorts/asia-the-pacific/vietnam/ninh-van-bay/sustainability/
A29: Six Senses Ninh Van Bay | B29: Current | C29: Culture & Heritage | D29: Local culture interpretation at Earth Lab / Langur Lounge | E29: Property mô tả Earth Lab và Langur Lounge là nơi du khách tìm hiểu về sustainability, local culture và wildlife conservation. | F29: Supporting | I29: C – Doanh nghiệp công bố định tính | J29: Yes – Experience-integrated | K29: Practice | L29: Có mô tả việc giới thiệu văn hóa, nhưng nguồn đã rà chưa cung cấp thực hành/chỉ số văn hóa cụ thể hơn. | M29: Breadth; Guest Experience; Evidence & Transparency | N29: Experience / Sustainability / Culture | O29: Tích hợp vào trải nghiệm khách | P29: Trang chính thức của khu nghỉ dưỡng | Q29: https://www.sixsenses.com/en/hotels-resorts/asia-the-pacific/vietnam/ninh-van-bay/sustainability/
A30: Six Senses Ninh Van Bay | B30: Current review | C30: Culture & Heritage | D30: Cultural heritage outcomes / metrics | E30: Trong các nguồn đã rà, chưa tìm thấy metric hoặc outcome cụ thể về bảo tồn di sản/văn hóa địa phương tại property. | F30: Data gap | I30: E – Chưa tìm thấy minh chứng cụ thể | J30: No – Governance | K30: Data gap | L30: Không có công khai minh chứng cụ thể không đồng nghĩa khu nghỉ dưỡng không thực hiện; chỉ phản ánh công bố được tìm thấy. | M30: Breadth; Evidence & Transparency | N30: Culture / Experience / Sustainability | O30: Tích hợp vào trải nghiệm khách | Q30: https://www.sixsenses.com/en/hotels-resorts/asia-the-pacific/vietnam/ninh-van-bay/sustainability/
A31: Six Senses Ninh Van Bay | B31: H1 2025 | C31: Guest Engagement | D31: Langur Discovery | E31: Khoảng 117 guests tham gia Langur Discovery do GreenViet researchers hướng dẫn trong 6 tháng đầu 2025. | F31: Core | G31: 117 | H31: guests | I31: D – Xác nhận từ đối tác bên ngoài | J31: Yes – Participatory | K31: Output | L31: Minh chứng trực tiếp từ đối tác về trải nghiệm phát triển bền vững có sự tham gia của khách. | M31: Guest Experience; Integration | N31: Experience / Biodiversity / Sustainability | O31: Tích hợp vào trải nghiệm khách | P31: GreenViet | Q31: https://greenviet.org/tin-tuc/truyen-cam-hung-yeu-va-bao-ve-thien-nhien-tai-six-senses-ninh-van-bay/
A32: Six Senses Ninh Van Bay | B32: 2025 | C32: Guest Engagement | D32: Nature experiences – annual participation | E32: GreenViet báo cáo 457 lượt du khách tham gia Step into the Wild, Langur Talk, Flora Walk hoặc Nature Hike trong năm 2025. | F32: Core | G32: 457 | H32: guest participations | I32: D – Xác nhận từ đối tác bên ngoài | J32: Yes – Participatory | K32: Output | L32: Không gộp với con số 457 người dân địa phương/học sinh, sinh viên do Six Senses công bố; đây là lượt khách tham gia theo GreenViet. | M32: Guest Experience; Evidence & Transparency | N32: Experience / Biodiversity / Sustainability | O32: Tích hợp vào trải nghiệm khách | P32: GreenViet | Q32: https://greenviet.org/tin-tuc/6-nam-dong-hanh-bao-ton-cha-va-chan-den-dau-an-hop-tac-greenviet-six-senses-ninh-van-bay/
A33: Six Senses Ninh Van Bay | B33: H1 2025 | C33: Guest Engagement | D33: Nature learning activities | E33: Khoảng 97 guests tham gia Langur Talk, Flora Walk, Snake Talk và Nature Hike. | F33: Supporting | G33: 97 | H33: guests | I33: D – Xác nhận từ đối tác bên ngoài | J33: Yes – Participatory | K33: Output | L33: Cho thấy phát triển bền vững được đóng gói thành trải nghiệm học hỏi, không chỉ truyền thông thụ động. | M33: Guest Experience; Integration | N33: Experience / Biodiversity | O33: Tích hợp vào trải nghiệm khách | P33: GreenViet | Q33: https://greenviet.org/tin-tuc/truyen-cam-hung-yeu-va-bao-ve-thien-nhien-tai-six-senses-ninh-van-bay/
A34: InterContinental Danang Sun Peninsula Resort | B34: 2026–2027 | C34: Energy & Climate | D34: Monthly energy monitoring & efficiency | E34: Sustainability Management Plan nêu resort theo dõi mức sử dụng năng lượng hàng tháng và ưu tiên thiết bị/giải pháp tiết kiệm năng lượng. | F34: Supporting | I34: C – Doanh nghiệp công bố định tính | J34: No – Back-of-house | K34: Practice | L34: Có quy trình quản lý rõ nhưng chưa thấy KPI cường độ sử dụng năng lượng/cấp khu nghỉ dưỡng mức giảm cụ thể trong nguồn này. | M34: Integration; Evidence & Transparency | N34: Engineering / Sustainability | O34: Tích hợp vào vận hành | P34: Kế hoạch Quản lý Phát triển bền vững của khu nghỉ dưỡng | Q34: https://www.danang.intercontinental.com/wp-content/uploads/2025/11/SUSTAINABILITY-MANAGEMENT-PLAN-2026-2027.pdf
A35: InterContinental Danang Sun Peninsula Resort | B35: 2026–2027 | C35: Water | D35: Water saving, reuse & wastewater management | E35: Plan nêu giám sát nguồn nước/nước thải, dùng thiết bị tiết kiệm nước, tái sử dụng nước phù hợp và khuyến khích towel/linen reuse. | F35: Core | I35: C – Doanh nghiệp công bố định tính | J35: Mixed | K35: Practice | L35: Thể hiện quản lý nước đã đi vào vận hành và khách hành vi, nhưng chưa có cường độ sử dụng nước KPI công khai trong nguồn rà soát. | M35: Integration; Guest Experience; Evidence & Transparency | N35: Engineering / Housekeeping / Rooms / Sustainability | O35: Tích hợp liên phòng ban | P35: Kế hoạch Quản lý Phát triển bền vững của khu nghỉ dưỡng | Q35: https://www.danang.intercontinental.com/wp-content/uploads/2025/11/SUSTAINABILITY-MANAGEMENT-PLAN-2026-2027.pdf
